Workbook

Sheet DATASET
A1: ALTERNATIF | B1: C1 | C1: C2 | D1: C3 | E1: C4 | F1: C5 | G1: C6 | H1: C7 | I1: C8 | J1: C9 | K1: C10
A2: AMANDA NABABAN | B2: 5 | C2: 5 | D2: 5 | E2: 4 | F2: 5 | G2: 5 | H2: 5 | I2: 4 | J2: 5 | K2: 4
A3: ARNITA NABABAN | B3: 5 | C3: 5 | D3: 4 | E3: 4 | F3: 4 | G3: 4 | H3: 5 | I3: 4 | J3: 5 | K3: 4
A4: MORES NABABAN | B4: 4 | C4: 5 | D4: 4 | E4: 5 | F4: 4 | G4: 4 | H4: 5 | I4: 3 | J4: 5 | K4: 4
A5: SARITUA MARPAUNG | B5: 5 | C5: 5 | D5: 5 | E5: 5 | F5: 5 | G5: 5 | H5: 5 | I5: 4 | J5: 5 | K5: 5
A6: ELSA NABABAN | B6: 4 | C6: 5 | D6: 4 | E6: 4 | F6: 4 | G6: 5 | H6: 5 | I6: 3 | J6: 5 | K6: 5
A7: HADI SAPUTRA | B7: 4 | C7: 4 | D7: 4 | E7: 5 | F7: 3 | G7: 4 | H7: 4 | I7: 2 | J7: 4 | K7: 5
A8: IRFAN AGUS | B8: 4 | C8: 4 | D8: 4 | E8: 5 | F8: 4 | G8: 4 | H8: 4 | I8: 3 | J8: 5 | K8: 5
A9: LESTARI SIBAGARIANG | B9: 4 | C9: 4 | D9: 4 | E9: 4 | F9: 3 | G9: 4 | H9: 4 | I9: 2 | J9: 4 | K9: 4
A10: JOSIA NABABAN | B10: 4 | C10: 4 | D10: 4 | E10: 4 | F10: 5 | G10: 5 | H10: 5 | I10: 4 | J10: 4 | K10: 5
A11: IRMA SIANIPAR | B11: 4 | C11: 5 | D11: 4 | E11: 4 | F11: 3 | G11: 4 | H11: 4 | I11: 3 | J11: 4 | K11: 5
A12: LAMTIUR NABABAN | B12: 4 | C12: 4 | D12: 3 | E12: 3 | F12: 4 | G12: 4 | H12: 4 | I12: 2 | J12: 4 | K12: 4
A13: RAHUL NABABAN | B13: 4 | C13: 3 | D13: 4 | E13: 4 | F13: 3 | G13: 4 | H13: 4 | I13: 2 | J13: 4 | K13: 4
... A21: JELMANRO SILITONGA | B21: 3 | C21: 3 | D21: 2 | E21: 3 | F21: 3 | G21: 3 | H21: 3 | I21: 2 | J21: 3 | K21: 3
F35: C1 | G35: 0.16 | I35: Kriteria | J35: Nama Kriteria
F36: C2 | G36: 0.14 | I36: C1 | J36: Nilai rata-rata raport
F37: C3 | G37: 0.08 | I37: C2 | J37: Ekstrakurikuler
F38: C4 | G38: 0.13 | I38: C3 | J38: Keaktifan
F39: C5 | G39: 0.07 | I39: C4 | J39: Keterampilan
F40: C6 | G40: 0.12 | I40: C5 | J40: Kepribadian
F41: C7 | G41: 0.09 | I41: C6 | J41: Kedisiplinan
F42: C8 | G42: 0.06 | I42: C7 | J42: Sikap
F43: C9 | G43: 0.05 | I43: C8 | J43: Sertifikat prestasi
F44: C10 | G44: 0.1 | I44: C9 | J44: Tanggung jawab
I45: C10 | J45: Absen

Sheet PERBANDINGAN + AGREGASI
A1: HASIL PERBANDINGAN PERANKINGAN MEREC + MARCOS DENGAN FUCOM + VIKOR
A2: RANKING | B2: MEREC + MARCOS | C2: FUCOM + VIKOR
A3: 1 | B3: =MARCOS!H79 -> SARITUA MARPAUNG | C3: =VIKOR!K50 -> SARITUA MARPAUNG | E3: BERDASARKAN PERBANDINGAN DARI KEDUA METODE TERSEBUT SISWA BERPRESTASI ADALAH SARITUA MARPAUNG, DIMANA PADA KEDUA METODE TERSEBUT MENEMPATI RANKING PERTAMA
A4: 2 | B4: =MARCOS!H80 -> AMANDA NABABAN | C4: =VIKOR!K51 -> AMANDA NABABAN
A5: 3 | B5: =MARCOS!H81 -> JOSIA NABABAN | C5: =VIKOR!K52 -> ELSA NABABAN
A6: 4 | B6: =MARCOS!H82 -> ARNITA NABABAN | C6: =VIKOR!K53 -> ARNITA NABABAN
A7: 5 | B7: =MARCOS!H83 -> ELSA NABABAN | C7: =VIKOR!K54 -> MORES NABABAN
A8: 6 | B8: =MARCOS!H84 -> MORES NABABAN | C8: =VIKOR!K55 -> JOSIA NABABAN | E8: PERBANDINGAN RANKING DENGAN MENGGUNAKAN METODE SAW DAN WP BERDASARKAN JURNAL YANG KAMI GUNAKAN
A9: 7 | B9: =MARCOS!H85 -> IRFAN AGUS | C9: =VIKOR!K56 -> IRFAN AGUS
A10: 8 | B10: =MARCOS!H86 -> IRMA SIANIPAR | C10: =VIKOR!K57 -> IRMA SIANIPAR
A11: 9 | B11: =MARCOS!H87 -> HADI SAPUTRA | C11: =VIKOR!K58 -> HADI SAPUTRA
A12: 10 | B12: =MARCOS!H88 -> ELFRIDA SITINJAK | C12: =VIKOR!K59 -> LESTARI SIBAGARIANG
A13: 11 | B13: =MARCOS!H89 -> LESTARI SIBAGARIANG | C13: =VIKOR!K60 -> RAHUL NABABAN
A14: 12 | B14: =MARCOS!H90 -> RAHUL NABABAN | C14: =VIKOR!K61 -> LAMTIUR NABABAN
A15: 13 | B15: =MARCOS!H91 -> LAMTIUR NABABAN | C15: =VIKOR!K62 -> ESTER NABABAN
A16: 14 | B16: =MARCOS!H92 -> HOSIANA NABABAN | C16: =VIKOR!K63 -> ELFRIDA SITINJAK
A17: 15 | B17: =MARCOS!H93 -> ESTER NABABAN | C17: =VIKOR!K64 -> HOSIANA NABABAN
A18: 16 | B18: =MARCOS!H94 -> CREDO NABABAN | C18: =VIKOR!K65 -> MORISCA SIBAGARIANG
A19: 17 | B19: =MARCOS!H95 -> ANWAR NABABAN | C19: =VIKOR!K66 -> ANWAR NABABAN
A20: 18 | B20: =MARCOS!H96 -> MORISCA SIBAGARIANG | C20: =VIKOR!K67 -> CREDO NABABAN
... A22: 20 | B22: =MARCOS!H98 -> SERDI SILITONGA | C22: =VIKOR!K69 -> SERDI SILITONGA
A34: REKAP PERBANDINGAN RANKING SEMUA METODE
A35: ALTERNATIF | B35: MEREC + MARCOS | C35: FUCOM + VIKOR | D35: SAW | E35: WP
A36: AMANDA NABABAN | B36: =MARCOS!G79 -> 2 | C36: =VIKOR!B72 -> 2 | D36: 2 | E36: 2
A37: ARNITA NABABAN | B37: =MARCOS!G80 -> 4 | C37: =VIKOR!B73 -> 4 | D37: 3 | E37: 3
A38: MORES NABABAN | B38: =MARCOS!G81 -> 6 | C38: =VIKOR!B74 -> 5 | D38: 6 | E38: 6
A39: SARITUA MARPAUNG | B39: =MARCOS!G82 -> 1 | C39: =VIKOR!B75 -> 1 | D39: 1 | E39: 1
A40: ELSA NABABAN | B40: =MARCOS!G83 -> 5 | C40: =VIKOR!B76 -> 3 | D40: 4 | E40: 4
A41: HADI SAPUTRA | B41: =MARCOS!G84 -> 9 | C41: =VIKOR!B77 -> 9 | D41: 9 | E41: 9
A42: IRFAN AGUS | B42: =MARCOS!G85 -> 7 | C42: =VIKOR!B78 -> 7 | D42: 7 | E42: 7
A43: LESTARI SIBAGARIANG | B43: =MARCOS!G86 -> 11 | C43: =VIKOR!B79 -> 10 | D43: 10 | E43: 10
A44: JOSIA NABABAN | B44: =MARCOS!G87 -> 3 | C44: =VIKOR!B80 -> 6 | D44: 5 | E44: 5
A45: IRMA SIANIPAR | B45: =MARCOS!G88 -> 8 | C45: =VIKOR!B81 -> 8 | D45: 8 | E45: 8
A46: LAMTIUR NABABAN | B46: =MARCOS!G89 -> 13 | C46: =VIKOR!B82 -> 12 | D46: 12 | E46: 12
A47: RAHUL NABABAN | B47: =MARCOS!G90 -> 12 | C47: =VIKOR!B83 -> 11 | D47: 13 | E47: 13
... A55: JELMANRO SILITONGA | B55: =MARCOS!G98 -> 19 | C55: =VIKOR!B91 -> 19 | D55: 19 | E55: 19
A56: BEST | B56: SARITUA MARPAUNG | C56: SARITUA MARPAUNG | D56: SARITUA MARPAUNG | E56: SARITUA MARPAUNG
A58: HITUNG GABUNGAN RANK DENGAN BORDA
A60: ALTERNATIF | B60: KE 1 | C60: KE 2 | D60: KE 3 | E60: KE 4 | F60: KE 5 | G60: KE 6 | H60: KE 7 | I60: KE 8 | J60: KE 9 | K60: KE 10 | L60: KE 11 | M60: KE 12 | N60: KE 13 | O60: KE 14 | P60: KE 15 | Q60: KE 16 | R60: KE 17 | S60: KE 18 | T60: KE 19 | U60: KE 20 | V60: SKOR BORDA | W60: PERINGKAT AKHIR
A61: AMANDA NABABAN | C61: 4 | V61: =(B61*$B$81)+(C61*$C$81)+(D61*$D$81)+(E61*$E$81)+(F61*$F$81)+(G61*$G$81)+(H61*$H$81)+(I61*$I$81)+(J61*$J$81)+(K61*$K$81)+(L61*$L$81)+(M61*$M$81)+(N61*$N$81)+(O61*$O$81)+(P61*$P$81)+(Q61*$Q$81)+(R61*$R$81)+(S61*$S$81)+(T61*$T$81)+(U61*$U$81) -> 72 | W61: =RANK(V61,$V$61:$V$80,0) -> 2
...

Sheet MEREC
A1: ALTERNATIF | B1: C1 | C1: C2 | D1: C3 | E1: C4 | F1: C5 | G1: C6 | H1: C7 | I1: C8 | J1: C9 | K1: C10
A2: AMANDA NABABAN | B2: 5 | C2: 5 | D2: 5 | E2: 4 | F2: 5 | G2: 5 | H2: 5 | I2: 4 | J2: 5 | K2: 4
A3: ARNITA NABABAN | B3: 5 | C3: 5 | D3: 4 | E3: 4 | F3: 4 | G3: 4 | H3: 5 | I3: 4 | J3: 5 | K3: 4
A4: MORES NABABAN | B4: 4 | C4: 5 | D4: 4 | E4: 5 | F4: 4 | G4: 4 | H4: 5 | I4: 3 | J4: 5 | K4: 4
A5: SARITUA MARPAUNG | B5: 5 | C5: 5 | D5: 5 | E5: 5 | F5: 5 | G5: 5 | H5: 5 | I5: 4 | J5: 5 | K5: 5
A6: ELSA NABABAN | B6: 4 | C6: 5 | D6: 4 | E6: 4 | F6: 4 | G6: 5 | H6: 5 | I6: 3 | J6: 5 | K6: 5
A7: HADI SAPUTRA | B7: 4 | C7: 4 | D7: 4 | E7: 5 | F7: 3 | G7: 4 | H7: 4 | I7: 2 | J7: 4 | K7: 5
A8: IRFAN AGUS | B8: 4 | C8: 4 | D8: 4 | E8: 5 | F8: 4 | G8: 4 | H8: 4 | I8: 3 | J8: 5 | K8: 5
A9: LESTARI SIBAGARIANG | B9: 4 | C9: 4 | D9: 4 | E9: 4 | F9: 3 | G9: 4 | H9: 4 | I9: 2 | J9: 4 | K9: 4
A10: JOSIA NABABAN | B10: 4 | C10: 4 | D10: 4 | E10: 4 | F10: 5 | G10: 5 | H10: 5 | I10: 4 | J10: 4 | K10: 5
A11: IRMA SIANIPAR | B11: 4 | C11: 5 | D11: 4 | E11: 4 | F11: 3 | G11: 4 | H11: 4 | I11: 3 | J11: 4 | K11: 5
A12: LAMTIUR NABABAN | B12: 4 | C12: 4 | D12: 3 | E12: 3 | F12: 4 | G12: 4 | H12: 4 | I12: 2 | J12: 4 | K12: 4
A13: RAHUL NABABAN | B13: 4 | C13: 3 | D13: 4 | E13: 4 | F13: 3 | G13: 4 | H13: 4 | I13: 2 | J13: 4 | K13: 4
... A22: AI | B22: 5 | C22: 5 | D22: 5 | E22: 5 | F22: 5 | G22: 5 | H22: 5 | I22: 4 | J22: 5 | K22: 5
A24: NORMALISASI | L24: PERHITUNGAN NILAI AWAL Si
A25: ALTERNATIF | B25: C1 | C25: C2 | D25: C3 | E25: C4 | F25: C5 | G25: C6 | H25: C7 | I25: C8 | J25: C9 | K25: C10 | L25: Si
A26: AMANDA NABABAN | B26: =B2/$B$22 -> 1 | C26: =C2/$C$22 -> 1 | D26: =D2/$D$22 -> 1 | E26: =E2/$E$22 -> 0.8 | F26: =F2/$F$22 -> 1 | G26: =G2/$G$22 -> 1 | H26: =H2/$H$22 -> 1 | I26: =I2/$I$22 -> 1 | J26: =J2/$J$22 -> 1 | K26: =K2/$K$22 -> 0.8 | L26: =LN(1 + (1/20 * (ABS(LN(B26)) + (ABS(LN(C26)) + (ABS(LN(D26)) + (ABS(LN(E26))+ (ABS(LN(F26)) + (ABS(LN(G26))+(ABS(LN(H26)) + (ABS(LN(I26)) + (ABS(LN(J26)) + (ABS(LN(K26)) )))))))))))) -> 0.022069033
A27: ARNITA NABABAN | B27: =B3/$B$22 -> 1 | C27: =C3/$C$22 -> 1 | D27: =D3/$D$22 -> 0.8 | E27: =E3/$E$22 -> 0.8 | F27: =F3/$F$22 -> 0.8 | G27: =G3/$G$22 -> 0.8 | H27: =H3/$H$22 -> 1 | I27: =I3/$I$22 -> 1 | J27: =J3/$J$22 -> 1 | K27: =K3/$K$22 -> 0.8 | L27: =LN(1 + (1/20 * (ABS(LN(B27)) + (ABS(LN(C27)) + (ABS(LN(D27)) + (ABS(LN(E27))+ (ABS(LN(F27)) + (ABS(LN(G27))+(ABS(LN(H27)) + (ABS(LN(I27)) + (ABS(LN(J27)) + (ABS(LN(K27)) )))))))))))) -> 0.054285407
A28: MORES NABABAN | B28: =B4/$B$22 -> 0.8 | C28: =C4/$C$22 -> 1 | D28: =D4/$D$22 -> 0.8 | E28: =E4/$E$22 -> 1 | F28: =F4/$F$22 -> 0.8 | G28: =G4/$G$22 -> 0.8 | H28: =H4/$H$22 -> 1 | I28: =I4/$I$22 -> 0.75 | J28: =J4/$J$22 -> 1 | K28: =K4/$K$22 -> 0.8 | L28: =LN(1 + (1/20 * (ABS(LN(B28)) + (ABS(LN(C28)) + (ABS(LN(D28)) + (ABS(LN(E28))+ (ABS(LN(F28)) + (ABS(LN(G28))+(ABS(LN(H28)) + (ABS(LN(I28)) + (ABS(LN(J28)) + (ABS(LN(K28)) )))))))))))) -> 0.067817506
A29: SARITUA MARPAUNG | B29: =B5/$B$22 -> 1 | C29: =C5/$C$22 -> 1 | D29: =D5/$D$22 -> 1 | E29: =E5/$E$22 -> 1 | F29: =F5/$F$22 -> 1 | G29: =G5/$G$22 -> 1 | H29: =H5/$H$22 -> 1 | I29: =I5/$I$22 -> 1 | J29: =J5/$J$22 -> 1 | K29: =K5/$K$22 -> 1 | L29: =LN(1 + (1/20 * (ABS(LN(B29)) + (ABS(LN(C29)) + (ABS(LN(D29)) + (ABS(LN(E29))+ (ABS(LN(F29)) + (ABS(LN(G29))+(ABS(LN(H29)) + (ABS(LN(I29)) + (ABS(LN(J29)) + (ABS(LN(K29)) )))))))))))) -> 0
A30: ELSA NABABAN | B30: =B6/$B$22 -> 0.8 | C30: =C6/$C$22 -> 1 | D30: =D6/$D$22 -> 0.8 | E30: =E6/$E$22 -> 0.8 | F30: =F6/$F$22 -> 0.8 | G30: =G6/$G$22 -> 1 | H30: =H6/$H$22 -> 1 | I30: =I6/$I$22 -> 0.75 | J30: =J6/$J$22 -> 1 | K30: =K6/$K$22 -> 1 | L30: =LN(1 + (1/20 * (ABS(LN(B30)) + (ABS(LN(C30)) + (ABS(LN(D30)) + (ABS(LN(E30))+ (ABS(LN(F30)) + (ABS(LN(G30))+(ABS(LN(H30)) + (ABS(LN(I30)) + (ABS(LN(J30)) + (ABS(LN(K30)) )))))))))))) -> 0.057337167
A31: HADI SAPUTRA | B31: =B7/$B$22 -> 0.8 | C31: =C7/$C$22 -> 0.8 | D31: =D7/$D$22 -> 0.8 | E31: =E7/$E$22 -> 1 | F31: =F7/$F$22 -> 0.6 | G31: =G7/$G$22 -> 0.8 | H31: =H7/$H$22 -> 0.8 | I31: =I7/$I$22 -> 0.5 | J31: =J7/$J$22 -> 0.8 | K31: =K7/$K$22 -> 1 | L31: =LN(1 + (1/20 * (ABS(LN(B31)) + (ABS(LN(C31)) + (ABS(LN(D31)) + (ABS(LN(E31))+ (ABS(LN(F31)) + (ABS(LN(G31))+(ABS(LN(H31)) + (ABS(LN(I31)) + (ABS(LN(J31)) + (ABS(LN(K31)) )))))))))))) -> 0.11968496
A32: IRFAN AGUS | B32: =B8/$B$22 -> 0.8 | C32: =C8/$C$22 -> 0.8 | D32: =D8/$D$22 -> 0.8 | E32: =E8/$E$22 -> 1 | F32: =F8/$F$22 -> 0.8 | G32: =G8/$G$22 -> 0.8 | H32: =H8/$H$22 -> 0.8 | I32: =I8/$I$22 -> 0.75 | J32: =J8/$J$22 -> 1 | K32: =K8/$K$22 -> 1 | L32: =LN(1 + (1/20 * (ABS(LN(B32)) + (ABS(LN(C32)) + (ABS(LN(D32)) + (ABS(LN(E32))+ (ABS(LN(F32)) + (ABS(LN(G32))+(ABS(LN(H32)) + (ABS(LN(I32)) + (ABS(LN(J32)) + (ABS(LN(K32)) )))))))))))) -> 0.078189147
A33: LESTARI SIBAGARIANG | B33: =B9/$B$22 -> 0.8 | C33: =C9/$C$22 -> 0.8 | D33: =D9/$D$22 -> 0.8 | E33: =E9/$E$22 -> 0.8 | F33: =F9/$F$22 -> 0.6 | G33: =G9/$G$22 -> 0.8 | H33: =H9/$H$22 -> 0.8 | I33: =I9/$I$22 -> 0.5 | J33: =J9/$J$22 -> 0.8 | K33: =K9/$K$22 -> 0.8 | L33: =LN(1 + (1/20 * (ABS(LN(B33)) + (ABS(LN(C33)) + (ABS(LN(D33)) + (ABS(LN(E33))+ (ABS(LN(F33)) + (ABS(LN(G33))+(ABS(LN(H33)) + (ABS(LN(I33)) + (ABS(LN(J33)) + (ABS(LN(K33)) )))))))))))) -> 0.13928884
A34: JOSIA NABABAN | B34: =B10/$B$22 -> 0.8 | C34: =C10/$C$22 -> 0.8 | D34: =D10/$D$22 -> 0.8 | E34: =E10/$E$22 -> 0.8 | F34: =F10/$F$22 -> 1 | G34: =G10/$G$22 -> 1 | H34: =H10/$H$22 -> 1 | I34: =I10/$I$22 -> 1 | J34: =J10/$J$22 -> 0.8 | K34: =K10/$K$22 -> 1 | L34: =LN(1 + (1/20 * (ABS(LN(B34)) + (ABS(LN(C34)) + (ABS(LN(D34)) + (ABS(LN(E34))+ (ABS(LN(F34)) + (ABS(LN(G34))+(ABS(LN(H34)) + (ABS(LN(I34)) + (ABS(LN(J34)) + (ABS(LN(K34)) )))))))))))) -> 0.054285407
A35: IRMA SIANIPAR | B35: =B11/$B$22 -> 0.8 | C35: =C11/$C$22 -> 1 | D35: =D11/$D$22 -> 0.8 | E35: =E11/$E$22 -> 0.8 | F35: =F11/$F$22 -> 0.6 | G35: =G11/$G$22 -> 0.8 | H35: =H11/$H$22 -> 0.8 | I35: =I11/$I$22 -> 0.75 | J35: =J11/$J$22 -> 0.8 | K35: =K11/$K$22 -> 1 | L35: =LN(1 + (1/20 * (ABS(LN(B35)) + (ABS(LN(C35)) + (ABS(LN(D35)) + (ABS(LN(E35))+ (ABS(LN(F35)) + (ABS(LN(G35))+(ABS(LN(H35)) + (ABS(LN(I35)) + (ABS(LN(J35)) + (ABS(LN(K35)) )))))))))))) -> 0.10153481
A36: LAMTIUR NABABAN | B36: =B12/$B$22 -> 0.8 | C36: =C12/$C$22 -> 0.8 | D36: =D12/$D$22 -> 0.6 | E36: =E12/$E$22 -> 0.6 | F36: =F12/$F$22 -> 0.8 | G36: =G12/$G$22 -> 0.8 | H36: =H12/$H$22 -> 0.8 | I36: =I12/$I$22 -> 0.5 | J36: =J12/$J$22 -> 0.8 | K36: =K12/$K$22 -> 0.8 | L36: =LN(1 + (1/20 * (ABS(LN(B36)) + (ABS(LN(C36)) + (ABS(LN(D36)) + (ABS(LN(E36))+ (ABS(LN(F36)) + (ABS(LN(G36))+(ABS(LN(H36)) + (ABS(LN(I36)) + (ABS(LN(J36)) + (ABS(LN(K36)) )))))))))))) -> 0.15172502
A37: RAHUL NABABAN | B37: =B13/$B$22 -> 0.8 | C37: =C13/$C$22 -> 0.6 | D37: =D13/$D$22 -> 0.8 | E37: =E13/$E$22 -> 0.8 | F37: =F13/$F$22 -> 0.6 | G37: =G13/$G$22 -> 0.8 | H37: =H13/$H$22 -> 0.8 | I37: =I13/$I$22 -> 0.5 | J37: =J13/$J$22 -> 0.8 | K37: =K13/$K$22 -> 0.8 | L37: =LN(1 + (1/20 * (ABS(LN(B37)) + (ABS(LN(C37)) + (ABS(LN(D37)) + (ABS(LN(E37))+ (ABS(LN(F37)) + (ABS(LN(G37))+(ABS(LN(H37)) + (ABS(LN(I37)) + (ABS(LN(J37)) + (ABS(LN(K37)) )))))))))))) -> 0.15172502
... A45: JELMANRO SILITONGA | B45: =B21/$B$22 -> 0.6 | C45: =C21/$C$22 -> 0.6 | D45: =D21/$D$22 -> 0.4 | E45: =E21/$E$22 -> 0.6 | F45: =F21/$F$22 -> 0.6 | G45: =G21/$G$22 -> 0.6 | H45: =H21/$H$22 -> 0.6 | I45: =I21/$I$22 -> 0.5 | J45: =J21/$J$22 -> 0.6 | K45: =K21/$K$22 -> 0.6 | L45: =LN(1 + (1/20 * (ABS(LN(B45)) + (ABS(LN(C45)) + (ABS(LN(D45)) + (ABS(LN(E45))+ (ABS(LN(F45)) + (ABS(LN(G45))+(ABS(LN(H45)) + (ABS(LN(I45)) + (ABS(LN(J45)) + (ABS(LN(K45)) )))))))))))) -> 0.25060473
A47: PERHITUNGAN PERFORMA ALTERNATIF
A48: ALTERNATIF | B48: C1 | C48: C2 | D48: C3 | E48: C4 | F48: C5 | G48: C6 | H48: C7 | I48: C8 | J48: C9 | K48: C10
A49: AMANDA NABABAN | B49: =LN(1 + (1/20 * (ABS(LN(C26)) + (ABS(LN(D26)) + (ABS(LN(E26))+ (ABS(LN(F26)) + (ABS(LN(G26))+(ABS(LN(H26)) + (ABS(LN(I26)) + (ABS(LN(J26)) + (ABS(LN(K26)) ))))))))))) -> 0.022069033 | C49: =LN(1 + (1/20 * (ABS(LN(B26)) + (ABS(LN(D26)) + (ABS(LN(E26))+ (ABS(LN(F26)) + (ABS(LN(G26))+(ABS(LN(H26)) + (ABS(LN(I26)) + (ABS(LN(J26)) + (ABS(LN(K26)) ))))))))))) -> 0.022069033 | D49: =LN(1 + (1/20 * (ABS(LN(B26)) + (ABS(LN(C26)) + (ABS(LN(E26))+ (ABS(LN(F26)) + (ABS(LN(G26))+(ABS(LN(H26)) + (ABS(LN(I26)) + (ABS(LN(J26)) + (ABS(LN(K26)) ))))))))))) -> 0.022069033 | E49: =LN(1 + (1/20 * (ABS(LN(B26)) + (ABS(LN(C26)) + (ABS(LN(D26)) + (ABS(LN(F26)) + (ABS(LN(G26))+(ABS(LN(H26)) + (ABS(LN(I26)) + (ABS(LN(J26)) + (ABS(LN(K26)) ))))))))))) -> 0.011095395 | F49: =LN(1 + (1/20 * (ABS(LN(B26)) + (ABS(LN(C26)) + (ABS(LN(D26)) + (ABS(LN(E26))+ (ABS(LN(G26))+(ABS(LN(H26)) + (ABS(LN(I26)) + (ABS(LN(J26)) + (ABS(LN(K26)) ))))))))))) -> 0.022069033 | G49: =LN(1 + (1/20 * (ABS(LN(B26)) + (ABS(LN(C26)) + (ABS(LN(D26)) + (ABS(LN(E26))+ (ABS(LN(F26)) + (ABS(LN(H26)) + (ABS(LN(I26)) + (ABS(LN(J26)) + (ABS(LN(K26)) ))))))))))) -> 0.022069033 | H49: =LN(1 + (1/20 * (ABS(LN(B26)) + (ABS(LN(C26)) + (ABS(LN(D26)) + (ABS(LN(E26))+ (ABS(LN(F26)) + (ABS(LN(G26))+(ABS(LN(I26)) + (ABS(LN(J26)) + (ABS(LN(K26)) ))))))))))) -> 0.022069033 | I49: =LN(1 + (1/20 * (ABS(LN(B26)) + (ABS(LN(C26)) + (ABS(LN(D26)) + (ABS(LN(E26))+ (ABS(LN(F26)) + (ABS(LN(G26))+(ABS(LN(H26)) + (ABS(LN(J26)) + (ABS(LN(K26)) ))))))))))) -> 0.022069033 | J49: =LN(1 + (1/20 * (ABS(LN(B26)) + (ABS(LN(C26)) + (ABS(LN(D26)) + (ABS(LN(E26))+ (ABS(LN(F26)) + (ABS(LN(G26))+(ABS(LN(H26)) + (ABS(LN(I26)) + (ABS(LN(K26)) ))))))))))) -> 0.022069033 | K49: =LN(1 + (1/20 * (ABS(LN(B26)) + (ABS(LN(C26)) + (ABS(LN(D26)) + (ABS(LN(E26))+ (ABS(LN(F26)) + (ABS(LN(G26))+(ABS(LN(H26)) + (ABS(LN(I26)) + (ABS(LN(J26)) ))))))))))) -> 0.011095395
A50: ARNITA NABABAN | B50: =LN(1 + (1/20 * (ABS(LN(C27)) + (ABS(LN(D27)) + (ABS(LN(E27))+ (ABS(LN(F27)) + (ABS(LN(G27))+(ABS(LN(H27)) + (ABS(LN(I27)) + (ABS(LN(J27)) + (ABS(LN(K27)) ))))))))))) -> 0.054285407 | C50: =LN(1 + (1/20 * (ABS(LN(B27)) + (ABS(LN(D27)) + (ABS(LN(E27))+ (ABS(LN(F27)) + (ABS(LN(G27))+(ABS(LN(H27)) + (ABS(LN(I27)) + (ABS(LN(J27)) + (ABS(LN(K27)) ))))))))))) -> 0.054285407 | D50: =LN(1 + (1/20 * (ABS(LN(B27)) + (ABS(LN(C27)) + (ABS(LN(E27))+ (ABS(LN(F27)) + (ABS(LN(G27))+(ABS(LN(H27)) + (ABS(LN(I27)) + (ABS(LN(J27)) + (ABS(LN(K27)) ))))))))))) -> 0.043661521 | E50: =LN(1 + (1/20 * (ABS(LN(B27)) + (ABS(LN(C27)) + (ABS(LN(D27)) + (ABS(LN(F27)) + (ABS(LN(G27))+(ABS(LN(H27)) + (ABS(LN(I27)) + (ABS(LN(J27)) + (ABS(LN(K27)) ))))))))))) -> 0.043661521 | F50: =LN(1 + (1/20 * (ABS(LN(B27)) + (ABS(LN(C27)) + (ABS(LN(D27)) + (ABS(LN(E27))+ (ABS(LN(G27))+(ABS(LN(H27)) + (ABS(LN(I27)) + (ABS(LN(J27)) + (ABS(LN(K27)) ))))))))))) -> 0.043661521 | G50: =LN(1 + (1/20 * (ABS(LN(B27)) + (ABS(LN(C27)) + (ABS(LN(D27)) + (ABS(LN(E27))+ (ABS(LN(F27)) + (ABS(LN(H27)) + (ABS(LN(I27)) + (ABS(LN(J27)) + (ABS(LN(K27)) ))))))))))) -> 0.043661521 | H50: =LN(1 + (1/20 * (ABS(LN(B27)) + (ABS(LN(C27)) + (ABS(LN(D27)) + (ABS(LN(E27))+ (ABS(LN(F27)) + (ABS(LN(G27))+(ABS(LN(I27)) + (ABS(LN(J27)) + (ABS(LN(K27)) ))))))))))) -> 0.054285407 | I50: =LN(1 + (1/20 * (ABS(LN(B27)) + (ABS(LN(C27)) + (ABS(LN(D27)) + (ABS(LN(E27))+ (ABS(LN(F27)) + (ABS(LN(G27))+(ABS(LN(H27)) + (ABS(LN(J27)) + (ABS(LN(K27)) ))))))))))) -> 0.054285407 | J50: =LN(1 + (1/20 * (ABS(LN(B27)) + (ABS(LN(C27)) + (ABS(LN(D27)) + (ABS(LN(E27))+ (ABS(LN(F27)) + (ABS(LN(G27))+(ABS(LN(H27)) + (ABS(LN(I27)) + (ABS(LN(K27)) ))))))))))) -> 0.054285407 | K50: =LN(1 + (1/20 * (ABS(LN(B27)) + (ABS(LN(C27)) + (ABS(LN(D27)) + (ABS(LN(E27))+ (ABS(LN(F27)) + (ABS(LN(G27))+(ABS(LN(H27)) + (ABS(LN(I27)) + (ABS(LN(J27)) ))))))))))) -> 0.043661521
A51: MORES NABABAN | B51: =LN(1 + (1/20 * (ABS(LN(C28)) + (ABS(LN(D28)) + (ABS(LN(E28))+ (ABS(LN(F28)) + (ABS(LN(G28))+(ABS(LN(H28)) + (ABS(LN(I28)) + (ABS(LN(J28)) + (ABS(LN(K28)) ))))))))))) -> 0.057337167 | C51: =LN(1 + (1/20 * (ABS(LN(B28)) + (ABS(LN(D28)) + (ABS(LN(E28))+ (ABS(LN(F28)) + (ABS(LN(G28))+(ABS(LN(H28)) + (ABS(LN(I28)) + (ABS(LN(J28)) + (ABS(LN(K28)) ))))))))))) -> 0.067817506 | D51: =LN(1 + (1/20 * (ABS(LN(B28)) + (ABS(LN(C28)) + (ABS(LN(E28))+ (ABS(LN(F28)) + (ABS(LN(G28))+(ABS(LN(H28)) + (ABS(LN(I28)) + (ABS(LN(J28)) + (ABS(LN(K28)) ))))))))))) -> 0.057337167 | E51: =LN(1 + (1/20 * (ABS(LN(B28)) + (ABS(LN(C28)) + (ABS(LN(D28)) + (ABS(LN(F28)) + (ABS(LN(G28))+(ABS(LN(H28)) + (ABS(LN(I28)) + (ABS(LN(J28)) + (ABS(LN(K28)) ))))))))))) -> 0.067817506 | F51: =LN(1 + (1/20 * (ABS(LN(B28)) + (ABS(LN(C28)) + (ABS(LN(D28)) + (ABS(LN(E28))+ (ABS(LN(G28))+(ABS(LN(H28)) + (ABS(LN(I28)) + (ABS(LN(J28)) + (ABS(LN(K28)) ))))))))))) -> 0.057337167 | G51: =LN(1 + (1/20 * (ABS(LN(B28)) + (ABS(LN(C28)) + (ABS(LN(D28)) + (ABS(LN(E28))+ (ABS(LN(F28)) + (ABS(LN(H28)) + (ABS(LN(I28)) + (ABS(LN(J28)) + (ABS(LN(K28)) ))))))))))) -> 0.057337167 | H51: =LN(1 + (1/20 * (ABS(LN(B28)) + (ABS(LN(C28)) + (ABS(LN(D28)) + (ABS(LN(E28))+ (ABS(LN(F28)) + (ABS(LN(G28))+(ABS(LN(I28)) + (ABS(LN(J28)) + (ABS(LN(K28)) ))))))))))) -> 0.067817506 | I51: =LN(1 + (1/20 * (ABS(LN(B28)) + (ABS(LN(C28)) + (ABS(LN(D28)) + (ABS(LN(E28))+ (ABS(LN(F28)) + (ABS(LN(G28))+(ABS(LN(H28)) + (ABS(LN(J28)) + (ABS(LN(K28)) ))))))))))) -> 0.054285407 | J51: =LN(1 + (1/20 * (ABS(LN(B28)) + (ABS(LN(C28)) + (ABS(LN(D28)) + (ABS(LN(E28))+ (ABS(LN(F28)) + (ABS(LN(G28))+(ABS(LN(H28)) + (ABS(LN(I28)) + (ABS(LN(K28)) ))))))))))) -> 0.067817506 | K51: =LN(1 + (1/20 * (ABS(LN(B28)) + (ABS(LN(C28)) + (ABS(LN(D28)) + (ABS(LN(E28))+ (ABS(LN(F28)) + (ABS(LN(G28))+(ABS(LN(H28)) + (ABS(LN(I28)) + (ABS(LN(J28)) ))))))))))) -> 0.057337167
A52: SARITUA MARPAUNG | B52: =LN(1 + (1/20 * (ABS(LN(C29)) + (ABS(LN(D29)) + (ABS(LN(E29))+ (ABS(LN(F29)) + (ABS(LN(G29))+(ABS(LN(H29)) + (ABS(LN(I29)) + (ABS(LN(J29)) + (ABS(LN(K29)) ))))))))))) -> 0 | C52: =LN(1 + (1/20 * (ABS(LN(B29)) + (ABS(LN(D29)) + (ABS(LN(E29))+ (ABS(LN(F29)) + (ABS(LN(G29))+(ABS(LN(H29)) + (ABS(LN(I29)) + (ABS(LN(J29)) + (ABS(LN(K29)) ))))))))))) -> 0 | D52: =LN(1 + (1/20 * (ABS(LN(B29)) + (ABS(LN(C29)) + (ABS(LN(E29))+ (ABS(LN(F29)) + (ABS(LN(G29))+(ABS(LN(H29)) + (ABS(LN(I29)) + (ABS(LN(J29)) + (ABS(LN(K29)) ))))))))))) -> 0 | E52: =LN(1 + (1/20 * (ABS(LN(B29)) + (ABS(LN(C29)) + (ABS(LN(D29)) + (ABS(LN(F29)) + (ABS(LN(G29))+(ABS(LN(H29)) + (ABS(LN(I29)) + (ABS(LN(J29)) + (ABS(LN(K29)) ))))))))))) -> 0 | F52: =LN(1 + (1/20 * (ABS(LN(B29)) + (ABS(LN(C29)) + (ABS(LN(D29)) + (ABS(LN(E29))+ (ABS(LN(G29))+(ABS(LN(H29)) + (ABS(LN(I29)) + (ABS(LN(J29)) + (ABS(LN(K29)) ))))))))))) -> 0 | G52: =LN(1 + (1/20 * (ABS(LN(B29)) + (ABS(LN(C29)) + (ABS(LN(D29)) + (ABS(LN(E29))+ (ABS(LN(F29)) + (ABS(LN(H29)) + (ABS(LN(I29)) + (ABS(LN(J29)) + (ABS(LN(K29)) ))))))))))) -> 0 | H52: =LN(1 + (1/20 * (ABS(LN(B29)) + (ABS(LN(C29)) + (ABS(LN(D29)) + (ABS(LN(E29))+ (ABS(LN(F29)) + (ABS(LN(G29))+(ABS(LN(I29)) + (ABS(LN(J29)) + (ABS(LN(K29)) ))))))))))) -> 0 | I52: =LN(1 + (1/20 * (ABS(LN(B29)) + (ABS(LN(C29)) + (ABS(LN(D29)) + (ABS(LN(E29))+ (ABS(LN(F29)) + (ABS(LN(G29))+(ABS(LN(H29)) + (ABS(LN(J29)) + (ABS(LN(K29)) ))))))))))) -> 0 | J52: =LN(1 + (1/20 * (ABS(LN(B29)) + (ABS(LN(C29)) + (ABS(LN(D29)) + (ABS(LN(E29))+ (ABS(LN(F29)) + (ABS(LN(G29))+(ABS(LN(H29)) + (ABS(LN(I29)) + (ABS(LN(K29)) ))))))))))) -> 0 | K52: =LN(1 + (1/20 * (ABS(LN(B29)) + (ABS(LN(C29)) + (ABS(LN(D29)) + (ABS(LN(E29))+ (ABS(LN(F29)) + (ABS(LN(G29))+(ABS(LN(H29)) + (ABS(LN(I29)) + (ABS(LN(J29)) ))))))))))) -> 0
A53: ELSA NABABAN | B53: =LN(1 + (1/20 * (ABS(LN(C30)) + (ABS(LN(D30)) + (ABS(LN(E30))+ (ABS(LN(F30)) + (ABS(LN(G30))+(ABS(LN(H30)) + (ABS(LN(I30)) + (ABS(LN(J30)) + (ABS(LN(K30)) ))))))))))) -> 0.046745825 | C53: =LN(1 + (1/20 * (ABS(LN(B30)) + (ABS(LN(D30)) + (ABS(LN(E30))+ (ABS(LN(F30)) + (ABS(LN(G30))+(ABS(LN(H30)) + (ABS(LN(I30)) + (ABS(LN(J30)) + (ABS(LN(K30)) ))))))))))) -> 0.057337167 | D53: =LN(1 + (1/20 * (ABS(LN(B30)) + (ABS(LN(C30)) + (ABS(LN(E30))+ (ABS(LN(F30)) + (ABS(LN(G30))+(ABS(LN(H30)) + (ABS(LN(I30)) + (ABS(LN(J30)) + (ABS(LN(K30)) ))))))))))) -> 0.046745825 | E53: =LN(1 + (1/20 * (ABS(LN(B30)) + (ABS(LN(C30)) + (ABS(LN(D30)) + (ABS(LN(F30)) + (ABS(LN(G30))+(ABS(LN(H30)) + (ABS(LN(I30)) + (ABS(LN(J30)) + (ABS(LN(K30)) ))))))))))) -> 0.046745825 | F53: =LN(1 + (1/20 * (ABS(LN(B30)) + (ABS(LN(C30)) + (ABS(LN(D30)) + (ABS(LN(E30))+ (ABS(LN(G30))+(ABS(LN(H30)) + (ABS(LN(I30)) + (ABS(LN(J30)) + (ABS(LN(K30)) ))))))))))) -> 0.046745825 | G53: =LN(1 + (1/20 * (ABS(LN(B30)) + (ABS(LN(C30)) + (ABS(LN(D30)) + (ABS(LN(E30))+ (ABS(LN(F30)) + (ABS(LN(H30)) + (ABS(LN(I30)) + (ABS(LN(J30)) + (ABS(LN(K30)) ))))))))))) -> 0.057337167 | H53: =LN(1 + (1/20 * (ABS(LN(B30)) + (ABS(LN(C30)) + (ABS(LN(D30)) + (ABS(LN(E30))+ (ABS(LN(F30)) + (ABS(LN(G30))+(ABS(LN(I30)) + (ABS(LN(J30)) + (ABS(LN(K30)) ))))))))))) -> 0.057337167 | I53: =LN(1 + (1/20 * (ABS(LN(B30)) + (ABS(LN(C30)) + (ABS(LN(D30)) + (ABS(LN(E30))+ (ABS(LN(F30)) + (ABS(LN(G30))+(ABS(LN(H30)) + (ABS(LN(J30)) + (ABS(LN(K30)) ))))))))))) -> 0.043661521 | J53: =LN(1 + (1/20 * (ABS(LN(B30)) + (ABS(LN(C30)) + (ABS(LN(D30)) + (ABS(LN(E30))+ (ABS(LN(F30)) + (ABS(LN(G30))+(ABS(LN(H30)) + (ABS(LN(I30)) + (ABS(LN(K30)) ))))))))))) -> 0.057337167 | K53: =LN(1 + (1/20 * (ABS(LN(B30)) + (ABS(LN(C30)) + (ABS(LN(D30)) + (ABS(LN(E30))+ (ABS(LN(F30)) + (ABS(LN(G30))+(ABS(LN(H30)) + (ABS(LN(I30)) + (ABS(LN(J30)) ))))))))))) -> 0.057337167
A54: HADI SAPUTRA | B54: =LN(1 + (1/20 * (ABS(LN(C31)) + (ABS(LN(D31)) + (ABS(LN(E31))+ (ABS(LN(F31)) + (ABS(LN(G31))+(ABS(LN(H31)) + (ABS(LN(I31)) + (ABS(LN(J31)) + (ABS(LN(K31)) ))))))))))) -> 0.109737 | C54: =LN(1 + (1/20 * (ABS(LN(B31)) + (ABS(LN(D31)) + (ABS(LN(E31))+ (ABS(LN(F31)) + (ABS(LN(G31))+(ABS(LN(H31)) + (ABS(LN(I31)) + (ABS(LN(J31)) + (ABS(LN(K31)) ))))))))))) -> 0.109737 | D54: =LN(1 + (1/20 * (ABS(LN(B31)) + (ABS(LN(C31)) + (ABS(LN(E31))+ (ABS(LN(F31)) + (ABS(LN(G31))+(ABS(LN(H31)) + (ABS(LN(I31)) + (ABS(LN(J31)) + (ABS(LN(K31)) ))))))))))) -> 0.109737 | E54: =LN(1 + (1/20 * (ABS(LN(B31)) + (ABS(LN(C31)) + (ABS(LN(D31)) + (ABS(LN(F31)) + (ABS(LN(G31))+(ABS(LN(H31)) + (ABS(LN(I31)) + (ABS(LN(J31)) + (ABS(LN(K31)) ))))))))))) -> 0.11968496 | F54: =LN(1 + (1/20 * (ABS(LN(B31)) + (ABS(LN(C31)) + (ABS(LN(D31)) + (ABS(LN(E31))+ (ABS(LN(G31))+(ABS(LN(H31)) + (ABS(LN(I31)) + (ABS(LN(J31)) + (ABS(LN(K31)) ))))))))))) -> 0.096764054 | G54: =LN(1 + (1/20 * (ABS(LN(B31)) + (ABS(LN(C31)) + (ABS(LN(D31)) + (ABS(LN(E31))+ (ABS(LN(F31)) + (ABS(LN(H31)) + (ABS(LN(I31)) + (ABS(LN(J31)) + (ABS(LN(K31)) ))))))))))) -> 0.109737 | H54: =LN(1 + (1/20 * (ABS(LN(B31)) + (ABS(LN(C31)) + (ABS(LN(D31)) + (ABS(LN(E31))+ (ABS(LN(F31)) + (ABS(LN(G31))+(ABS(LN(I31)) + (ABS(LN(J31)) + (ABS(LN(K31)) ))))))))))) -> 0.109737 | I54: =LN(1 + (1/20 * (ABS(LN(B31)) + (ABS(LN(C31)) + (ABS(LN(D31)) + (ABS(LN(E31))+ (ABS(LN(F31)) + (ABS(LN(G31))+(ABS(LN(H31)) + (ABS(LN(J31)) + (ABS(LN(K31)) ))))))))))) -> 0.08845432 | J54: =LN(1 + (1/20 * (ABS(LN(B31)) + (ABS(LN(C31)) + (ABS(LN(D31)) + (ABS(LN(E31))+ (ABS(LN(F31)) + (ABS(LN(G31))+(ABS(LN(H31)) + (ABS(LN(I31)) + (ABS(LN(K31)) ))))))))))) -> 0.109737 | K54: =LN(1 + (1/20 * (ABS(LN(B31)) + (ABS(LN(C31)) + (ABS(LN(D31)) + (ABS(LN(E31))+ (ABS(LN(F31)) + (ABS(LN(G31))+(ABS(LN(H31)) + (ABS(LN(I31)) + (ABS(LN(J31)) ))))))))))) -> 0.11968496
A55: IRFAN AGUS | B55: =LN(1 + (1/20 * (ABS(LN(C32)) + (ABS(LN(D32)) + (ABS(LN(E32))+ (ABS(LN(F32)) + (ABS(LN(G32))+(ABS(LN(H32)) + (ABS(LN(I32)) + (ABS(LN(J32)) + (ABS(LN(K32)) ))))))))))) -> 0.067817506 | C55: =LN(1 + (1/20 * (ABS(LN(B32)) + (ABS(LN(D32)) + (ABS(LN(E32))+ (ABS(LN(F32)) + (ABS(LN(G32))+(ABS(LN(H32)) + (ABS(LN(I32)) + (ABS(LN(J32)) + (ABS(LN(K32)) ))))))))))) -> 0.067817506 | D55: =LN(1 + (1/20 * (ABS(LN(B32)) + (ABS(LN(C32)) + (ABS(LN(E32))+ (ABS(LN(F32)) + (ABS(LN(G32))+(ABS(LN(H32)) + (ABS(LN(I32)) + (ABS(LN(J32)) + (ABS(LN(K32)) ))))))))))) -> 0.067817506 | E55: =LN(1 + (1/20 * (ABS(LN(B32)) + (ABS(LN(C32)) + (ABS(LN(D32)) + (ABS(LN(F32)) + (ABS(LN(G32))+(ABS(LN(H32)) + (ABS(LN(I32)) + (ABS(LN(J32)) + (ABS(LN(K32)) ))))))))))) -> 0.078189147 | F55: =LN(1 + (1/20 * (ABS(LN(B32)) + (ABS(LN(C32)) + (ABS(LN(D32)) + (ABS(LN(E32))+ (ABS(LN(G32))+(ABS(LN(H32)) + (ABS(LN(I32)) + (ABS(LN(J32)) + (ABS(LN(K32)) ))))))))))) -> 0.067817506 | G55: =LN(1 + (1/20 * (ABS(LN(B32)) + (ABS(LN(C32)) + (ABS(LN(D32)) + (ABS(LN(E32))+ (ABS(LN(F32)) + (ABS(LN(H32)) + (ABS(LN(I32)) + (ABS(LN(J32)) + (ABS(LN(K32)) ))))))))))) -> 0.067817506 | H55: =LN(1 + (1/20 * (ABS(LN(B32)) + (ABS(LN(C32)) + (ABS(LN(D32)) + (ABS(LN(E32))+ (ABS(LN(F32)) + (ABS(LN(G32))+(ABS(LN(I32)) + (ABS(LN(J32)) + (ABS(LN(K32)) ))))))))))) -> 0.067817506 | I55: =LN(1 + (1/20 * (ABS(LN(B32)) + (ABS(LN(C32)) + (ABS(LN(D32)) + (ABS(LN(E32))+ (ABS(LN(F32)) + (ABS(LN(G32))+(ABS(LN(H32)) + (ABS(LN(J32)) + (ABS(LN(K32)) ))))))))))) -> 0.064797611 | J55: =LN(1 + (1/20 * (ABS(LN(B32)) + (ABS(LN(C32)) + (ABS(LN(D32)) + (ABS(LN(E32))+ (ABS(LN(F32)) + (ABS(LN(G32))+(ABS(LN(H32)) + (ABS(LN(I32)) + (ABS(LN(K32)) ))))))))))) -> 0.078189147 | K55: =LN(1 + (1/20 * (ABS(LN(B32)) + (ABS(LN(C32)) + (ABS(LN(D32)) + (ABS(LN(E32))+ (ABS(LN(F32)) + (ABS(LN(G32))+(ABS(LN(H32)) + (ABS(LN(I32)) + (ABS(LN(J32)) ))))))))))) -> 0.078189147
A56: LESTARI SIBAGARIANG | B56: =LN(1 + (1/20 * (ABS(LN(C33)) + (ABS(LN(D33)) + (ABS(LN(E33))+ (ABS(LN(F33)) + (ABS(LN(G33))+(ABS(LN(H33)) + (ABS(LN(I33)) + (ABS(LN(J33)) + (ABS(LN(K33)) ))))))))))) -> 0.12953494 | C56: =LN(1 + (1/20 * (ABS(LN(B33)) + (ABS(LN(D33)) + (ABS(LN(E33))+ (ABS(LN(F33)) + (ABS(LN(G33))+(ABS(LN(H33)) + (ABS(LN(I33)) + (ABS(LN(J33)) + (ABS(LN(K33)) ))))))))))) -> 0.12953494 | D56: =LN(1 + (1/20 * (ABS(LN(B33)) + (ABS(LN(C33)) + (ABS(LN(E33))+ (ABS(LN(F33)) + (ABS(LN(G33))+(ABS(LN(H33)) + (ABS(LN(I33)) + (ABS(LN(J33)) + (ABS(LN(K33)) ))))))))))) -> 0.12953494 | E56: =LN(1 + (1/20 * (ABS(LN(B33)) + (ABS(LN(C33)) + (ABS(LN(D33)) + (ABS(LN(F33)) + (ABS(LN(G33))+(ABS(LN(H33)) + (ABS(LN(I33)) + (ABS(LN(J33)) + (ABS(LN(K33)) ))))))))))) -> 0.12953494 | F56: =LN(1 + (1/20 * (ABS(LN(B33)) + (ABS(LN(C33)) + (ABS(LN(D33)) + (ABS(LN(E33))+ (ABS(LN(G33))+(ABS(LN(H33)) + (ABS(LN(I33)) + (ABS(LN(J33)) + (ABS(LN(K33)) ))))))))))) -> 0.11681793 | G56: =LN(1 + (1/20 * (ABS(LN(B33)) + (ABS(LN(C33)) + (ABS(LN(D33)) + (ABS(LN(E33))+ (ABS(LN(F33)) + (ABS(LN(H33)) + (ABS(LN(I33)) + (ABS(LN(J33)) + (ABS(LN(K33)) ))))))))))) -> 0.12953494 | H56: =LN(1 + (1/20 * (ABS(LN(B33)) + (ABS(LN(C33)) + (ABS(LN(D33)) + (ABS(LN(E33))+ (ABS(LN(F33)) + (ABS(LN(G33))+(ABS(LN(I33)) + (ABS(LN(J33)) + (ABS(LN(K33)) ))))))))))) -> 0.12953494 | I56: =LN(1 + (1/20 * (ABS(LN(B33)) + (ABS(LN(C33)) + (ABS(LN(D33)) + (ABS(LN(E33))+ (ABS(LN(F33)) + (ABS(LN(G33))+(ABS(LN(H33)) + (ABS(LN(J33)) + (ABS(LN(K33)) ))))))))))) -> 0.10867385 | J56: =LN(1 + (1/20 * (ABS(LN(B33)) + (ABS(LN(C33)) + (ABS(LN(D33)) + (ABS(LN(E33))+ (ABS(LN(F33)) + (ABS(LN(G33))+(ABS(LN(H33)) + (ABS(LN(I33)) + (ABS(LN(K33)) ))))))))))) -> 0.12953494 | K56: =LN(1 + (1/20 * (ABS(LN(B33)) + (ABS(LN(C33)) + (ABS(LN(D33)) + (ABS(LN(E33))+ (ABS(LN(F33)) + (ABS(LN(G33))+(ABS(LN(H33)) + (ABS(LN(I33)) + (ABS(LN(J33)) ))))))))))) -> 0.12953494
A57: JOSIA NABABAN | B57: =LN(1 + (1/20 * (ABS(LN(C34)) + (ABS(LN(D34)) + (ABS(LN(E34))+ (ABS(LN(F34)) + (ABS(LN(G34))+(ABS(LN(H34)) + (ABS(LN(I34)) + (ABS(LN(J34)) + (ABS(LN(K34)) ))))))))))) -> 0.043661521 | C57: =LN(1 + (1/20 * (ABS(LN(B34)) + (ABS(LN(D34)) + (ABS(LN(E34))+ (ABS(LN(F34)) + (ABS(LN(G34))+(ABS(LN(H34)) + (ABS(LN(I34)) + (ABS(LN(J34)) + (ABS(LN(K34)) ))))))))))) -> 0.043661521 | D57: =LN(1 + (1/20 * (ABS(LN(B34)) + (ABS(LN(C34)) + (ABS(LN(E34))+ (ABS(LN(F34)) + (ABS(LN(G34))+(ABS(LN(H34)) + (ABS(LN(I34)) + (ABS(LN(J34)) + (ABS(LN(K34)) ))))))))))) -> 0.043661521 | E57: =LN(1 + (1/20 * (ABS(LN(B34)) + (ABS(LN(C34)) + (ABS(LN(D34)) + (ABS(LN(F34)) + (ABS(LN(G34))+(ABS(LN(H34)) + (ABS(LN(I34)) + (ABS(LN(J34)) + (ABS(LN(K34)) ))))))))))) -> 0.043661521 | F57: =LN(1 + (1/20 * (ABS(LN(B34)) + (ABS(LN(C34)) + (ABS(LN(D34)) + (ABS(LN(E34))+ (ABS(LN(G34))+(ABS(LN(H34)) + (ABS(LN(I34)) + (ABS(LN(J34)) + (ABS(LN(K34)) ))))))))))) -> 0.054285407 | G57: =LN(1 + (1/20 * (ABS(LN(B34)) + (ABS(LN(C34)) + (ABS(LN(D34)) + (ABS(LN(E34))+ (ABS(LN(F34)) + (ABS(LN(H34)) + (ABS(LN(I34)) + (ABS(LN(J34)) + (ABS(LN(K34)) ))))))))))) -> 0.054285407 | H57: =LN(1 + (1/20 * (ABS(LN(B34)) + (ABS(LN(C34)) + (ABS(LN(D34)) + (ABS(LN(E34))+ (ABS(LN(F34)) + (ABS(LN(G34))+(ABS(LN(I34)) + (ABS(LN(J34)) + (ABS(LN(K34)) ))))))))))) -> 0.054285407 | I57: =LN(1 + (1/20 * (ABS(LN(B34)) + (ABS(LN(C34)) + (ABS(LN(D34)) + (ABS(LN(E34))+ (ABS(LN(F34)) + (ABS(LN(G34))+(ABS(LN(H34)) + (ABS(LN(J34)) + (ABS(LN(K34)) ))))))))))) -> 0.054285407 | J57: =LN(1 + (1/20 * (ABS(LN(B34)) + (ABS(LN(C34)) + (ABS(LN(D34)) + (ABS(LN(E34))+ (ABS(LN(F34)) + (ABS(LN(G34))+(ABS(LN(H34)) + (ABS(LN(I34)) + (ABS(LN(K34)) ))))))))))) -> 0.043661521 | K57: =LN(1 + (1/20 * (ABS(LN(B34)) + (ABS(LN(C34)) + (ABS(LN(D34)) + (ABS(LN(E34))+ (ABS(LN(F34)) + (ABS(LN(G34))+(ABS(LN(H34)) + (ABS(LN(I34)) + (ABS(LN(J34)) ))))))))))) -> 0.054285407
...

Sheet MARCOS
A1: PERHITUNGAN MARCOS DENGAN BOBOT MEREC
A2: ALTERNATIF | B2: C1 | C2: C2 | D2: C3 | E2: C4 | F2: C5 | G2: C6 | H2: C7 | I2: C8 | J2: C9 | K2: C10
A3: AMANDA NABABAN | B3: 5 | C3: 5 | D3: 5 | E3: 4 | F3: 5 | G3: 5 | H3: 5 | I3: 4 | J3: 5 | K3: 4
A4: ARNITA NABABAN | B4: 5 | C4: 5 | D4: 4 | E4: 4 | F4: 4 | G4: 4 | H4: 5 | I4: 4 | J4: 5 | K4: 4
A5: MORES NABABAN | B5: 4 | C5: 5 | D5: 4 | E5: 5 | F5: 4 | G5: 4 | H5: 5 | I5: 3 | J5: 5 | K5: 4
A6: SARITUA MARPAUNG | B6: 5 | C6: 5 | D6: 5 | E6: 5 | F6: 5 | G6: 5 | H6: 5 | I6: 4 | J6: 5 | K6: 5
A7: ELSA NABABAN | B7: 4 | C7: 5 | D7: 4 | E7: 4 | F7: 4 | G7: 5 | H7: 5 | I7: 3 | J7: 5 | K7: 5
A8: HADI SAPUTRA | B8: 4 | C8: 4 | D8: 4 | E8: 5 | F8: 3 | G8: 4 | H8: 4 | I8: 2 | J8: 4 | K8: 5
A9: IRFAN AGUS | B9: 4 | C9: 4 | D9: 4 | E9: 5 | F9: 4 | G9: 4 | H9: 4 | I9: 3 | J9: 5 | K9: 5
A10: LESTARI SIBAGARIANG | B10: 4 | C10: 4 | D10: 4 | E10: 4 | F10: 3 | G10: 4 | H10: 4 | I10: 2 | J10: 4 | K10: 4
A11: JOSIA NABABAN | B11: 4 | C11: 4 | D11: 4 | E11: 4 | F11: 5 | G11: 5 | H11: 5 | I11: 4 | J11: 4 | K11: 5
A12: IRMA SIANIPAR | B12: 4 | C12: 5 | D12: 4 | E12: 4 | F12: 3 | G12: 4 | H12: 4 | I12: 3 | J12: 4 | K12: 5
A13: LAMTIUR NABABAN | B13: 4 | C13: 4 | D13: 3 | E13: 3 | F13: 4 | G13: 4 | H13: 4 | I13: 2 | J13: 4 | K13: 4
A14: RAHUL NABABAN | B14: 4 | C14: 3 | D14: 4 | E14: 4 | F14: 3 | G14: 4 | H14: 4 | I14: 2 | J14: 4 | K14: 4
... A22: JELMANRO SILITONGA | B22: 3 | C22: 3 | D22: 2 | E22: 3 | F22: 3 | G22: 3 | H22: 3 | I22: 2 | J22: 3 | K22: 3
A23: AI | B23: =MAX(B3:B22) -> 5 | C23: =MAX(C3:C22) -> 5 | D23: =MAX(D3:D22) -> 5 | E23: =MAX(E3:E22) -> 5 | F23: =MAX(F3:F22) -> 5 | G23: =MAX(G3:G22) -> 5 | H23: =MAX(H3:H22) -> 5 | I23: =MAX(I3:I22) -> 4 | J23: =MAX(J3:J22) -> 5 | K23: 5
A24: AAI | B24: =min(B3:B22) -> 3 | C24: =min(C3:C22) -> 2 | D24: =min(D3:D22) -> 2 | E24: =min(E3:E22) -> 3 | F24: =min(F3:F22) -> 3 | G24: =min(G3:G22) -> 3 | H24: =min(H3:H22) -> 3 | I24: =min(I3:I22) -> 1 | J24: =min(J3:J22) -> 3 | K24: 3
A27: NORMALISASI BOBOT
A28: ALTERNATIF | B28: C1 | C28: C2 | D28: C3 | E28: C4 | F28: C5 | G28: C6 | H28: C7 | I28: C8 | J28: C9 | K28: C10
A29: BOBOT | B29: =MEREC!B76 -> 0.07383637 | C29: =MEREC!C76 -> 0.072889006 | D29: =MEREC!D76 -> 0.10606734 | E29: =MEREC!E76 -> 0.11236577 | F29: =MEREC!F76 -> 0.11352603 | G29: =MEREC!G76 -> 0.098551866 | H29: =MEREC!H76 -> 0.08007078 | I29: =MEREC!I76 -> 0.16671903 | ... K29: =MEREC!K76 -> 0.091397537
A30: AMANDA NABABAN | B30: =MEREC!B26 -> 1 | C30: =MEREC!C26 -> 1 | D30: =MEREC!D26 -> 1 | E30: =MEREC!E26 -> 0.8 | F30: =MEREC!F26 -> 1 | G30: =MEREC!G26 -> 1 | H30: =MEREC!H26 -> 1 | I30: =MEREC!I26 -> 1 | ... K30: =MEREC!K26 -> 0.8
A31: ARNITA NABABAN | B31: =MEREC!B27 -> 1 | C31: =MEREC!C27 -> 1 | D31: =MEREC!D27 -> 0.8 | E31: =MEREC!E27 -> 0.8 | F31: =MEREC!F27 -> 0.8 | G31: =MEREC!G27 -> 0.8 | H31: =MEREC!H27 -> 1 | I31: =MEREC!I27 -> 1 | ... K31: =MEREC!K27 -> 0.8
A32: MORES NABABAN | B32: =MEREC!B28 -> 0.8 | C32: =MEREC!C28 -> 1 | D32: =MEREC!D28 -> 0.8 | E32: =MEREC!E28 -> 1 | F32: =MEREC!F28 -> 0.8 | G32: =MEREC!G28 -> 0.8 | H32: =MEREC!H28 -> 1 | I32: =MEREC!I28 -> 0.75 | ... K32: =MEREC!K28 -> 0.8
A33: SARITUA MARPAUNG | B33: =MEREC!B29 -> 1 | C33: =MEREC!C29 -> 1 | D33: =MEREC!D29 -> 1 | E33: =MEREC!E29 -> 1 | F33: =MEREC!F29 -> 1 | G33: =MEREC!G29 -> 1 | H33: =MEREC!H29 -> 1 | I33: =MEREC!I29 -> 1 | ... K33: =MEREC!K29 -> 1
A34: ELSA NABABAN | B34: =MEREC!B30 -> 0.8 | C34: =MEREC!C30 -> 1 | D34: =MEREC!D30 -> 0.8 | E34: =MEREC!E30 -> 0.8 | F34: =MEREC!F30 -> 0.8 | G34: =MEREC!G30 -> 1 | H34: =MEREC!H30 -> 1 | I34: =MEREC!I30 -> 0.75 | ... K34: =MEREC!K30 -> 1
A35: HADI SAPUTRA | B35: =MEREC!B31 -> 0.8 | C35: =MEREC!C31 -> 0.8 | D35: =MEREC!D31 -> 0.8 | E35: =MEREC!E31 -> 1 | F35: =MEREC!F31 -> 0.6 | G35: =MEREC!G31 -> 0.8 | H35: =MEREC!H31 -> 0.8 | I35: =MEREC!I31 -> 0.5 | ... K35: =MEREC!K31 -> 1
A36: IRFAN AGUS | B36: =MEREC!B32 -> 0.8 | C36: =MEREC!C32 -> 0.8 | D36: =MEREC!D32 -> 0.8 | E36: =MEREC!E32 -> 1 | F36: =MEREC!F32 -> 0.8 | G36: =MEREC!G32 -> 0.8 | H36: =MEREC!H32 -> 0.8 | I36: =MEREC!I32 -> 0.75 | ... K36: =MEREC!K32 -> 1
A37: LESTARI SIBAGARIANG | B37: =MEREC!B33 -> 0.8 | C37: =MEREC!C33 -> 0.8 | D37: =MEREC!D33 -> 0.8 | E37: =MEREC!E33 -> 0.8 | F37: =MEREC!F33 -> 0.6 | G37: =MEREC!G33 -> 0.8 | H37: =MEREC!H33 -> 0.8 | I37: =MEREC!I33 -> 0.5 | ... K37: =MEREC!K33 -> 0.8
A38: JOSIA NABABAN | B38: =MEREC!B34 -> 0.8 | C38: =MEREC!C34 -> 0.8 | D38: =MEREC!D34 -> 0.8 | E38: =MEREC!E34 -> 0.8 | F38: =MEREC!F34 -> 1 | G38: =MEREC!G34 -> 1 | H38: =MEREC!H34 -> 1 | I38: =MEREC!I34 -> 1 | ... K38: =MEREC!K34 -> 1
A39: IRMA SIANIPAR | B39: =MEREC!B35 -> 0.8 | C39: =MEREC!C35 -> 1 | D39: =MEREC!D35 -> 0.8 | E39: =MEREC!E35 -> 0.8 | F39: =MEREC!F35 -> 0.6 | G39: =MEREC!G35 -> 0.8 | H39: =MEREC!H35 -> 0.8 | I39: =MEREC!I35 -> 0.75 | ... K39: =MEREC!K35 -> 1
A40: LAMTIUR NABABAN | B40: =MEREC!B36 -> 0.8 | C40: =MEREC!C36 -> 0.8 | D40: =MEREC!D36 -> 0.6 | E40: =MEREC!E36 -> 0.6 | F40: =MEREC!F36 -> 0.8 | G40: =MEREC!G36 -> 0.8 | H40: =MEREC!H36 -> 0.8 | I40: =MEREC!I36 -> 0.5 | ... K40: =MEREC!K36 -> 0.8
A41: RAHUL NABABAN | B41: =MEREC!B37 -> 0.8 | C41: =MEREC!C37 -> 0.6 | D41: =MEREC!D37 -> 0.8 | E41: =MEREC!E37 -> 0.8 | F41: =MEREC!F37 -> 0.6 | G41: =MEREC!G37 -> 0.8 | H41: =MEREC!H37 -> 0.8 | I41: =MEREC!I37 -> 0.5 | ... K41: =MEREC!K37 -> 0.8
... A49: JELMANRO SILITONGA | B49: =MEREC!B45 -> 0.6 | C49: =MEREC!C45 -> 0.6 | D49: =MEREC!D45 -> 0.4 | E49: =MEREC!E45 -> 0.6 | F49: =MEREC!F45 -> 0.6 | G49: =MEREC!G45 -> 0.6 | H49: =MEREC!H45 -> 0.6 | I49: =MEREC!I45 -> 0.5 | ... K49: =MEREC!K45 -> 0.6
A50: AI | B50: =B23/$B$23 -> 1 | C50: =C23/$C$23 -> 1 | D50: =D23/$D$23 -> 1 | E50: =E23/$E$23 -> 1 | F50: =F23/$F$23 -> 1 | G50: =G23/$G$23 -> 1 | H50: =H23/$H$23 -> 1 | I50: =I23/$I$23 -> 1 | J50: =J23/$J$23 -> 1 | K50: =K23/$K$23 -> 1
A51: AAI | B51: =B24/$B$23 -> 0.6 | C51: =C24/$C$23 -> 0.4 | D51: =D24/$D$23 -> 0.4 | E51: =E24/$E$23 -> 0.6 | F51: =F24/$F$23 -> 0.6 | G51: =G24/$G$23 -> 0.6 | H51: =H24/$H$23 -> 0.6 | I51: =I24/$I$23 -> 0.25 | J51: =J24/$J$23 -> 0.6 | K51: =K24/$K$23 -> 0.6
A53: HASIL NORMALISASI TERBOBOT | L53: PERHITUNGAN NILAI UTILITAS
A54: ALTERNATIF | B54: C1 | C54: C2 | D54: C3 | E54: C4 | F54: C5 | G54: C6 | H54: C7 | I54: C8 | J54: C9 | K54: C10 | L54: Si | M54: WSM dengan BOBOT MEREC | N54: Rank WSM
A55: AMANDA NABABAN | B55: =$B$29*B30 -> 0.07383637 | C55: =$C$29*C30 -> 0.072889006 | D55: =$D$29*D30 -> 0.10606734 | E55: =$E$29*E30 -> 0.089892612 | F55: =$F$29*F30 -> 0.11352603 | G55: =$G$29*G30 -> 0.098551866 | H55: =$H$29*H30 -> 0.08007078 | I55: =$I$29*I30 -> 0.16671903 | J55: =$J$29*J30 -> 0.084576274 | K55: =$K$29*K30 -> 0.073118029 | L55: =SUM(B55:K55) -> 0.95924734 | M55: =SUM(B55:K55) -> 0.95924734 | N55: =RANK(M55,$M$55:$M$74,0) -> 2
A56: ARNITA NABABAN | B56: =$B$29*B31 -> 0.07383637 | C56: =$C$29*C31 -> 0.072889006 | D56: =$D$29*D31 -> 0.084853871 | E56: =$E$29*E31 -> 0.089892612 | F56: =$F$29*F31 -> 0.090820825 | G56: =$G$29*G31 -> 0.078841493 | H56: =$H$29*H31 -> 0.08007078 | I56: =$I$29*I31 -> 0.16671903 | J56: =$J$29*J31 -> 0.084576274 | K56: =$K$29*K31 -> 0.073118029 | L56: =SUM(B56:K56) -> 0.89561829 | M56: =SUM(B56:K56) -> 0.89561829 | N56: =RANK(M56,$M$55:$M$74,0) -> 4
A57: MORES NABABAN | B57: =$B$29*B32 -> 0.059069096 | C57: =$C$29*C32 -> 0.072889006 | D57: =$D$29*D32 -> 0.084853871 | E57: =$E$29*E32 -> 0.11236577 | F57: =$F$29*F32 -> 0.090820825 | G57: =$G$29*G32 -> 0.078841493 | H57: =$H$29*H32 -> 0.08007078 | I57: =$I$29*I32 -> 0.12503927 | J57: =$J$29*J32 -> 0.084576274 | K57: =$K$29*K32 -> 0.073118029 | L57: =SUM(B57:K57) -> 0.86164441 | M57: =SUM(B57:K57) -> 0.86164441 | N57: =RANK(M57,$M$55:$M$74,0) -> 6
...

Sheet FUCOM
A1: ALTERNATIF | B1: C1 | C1: C2 | D1: C3 | E1: C4 | F1: C5 | G1: C6 | H1: C7 | I1: C8 | J1: C9 | K1: C10
A2: AMANDA NABABAN | B2: 5 | C2: 5 | D2: 5 | E2: 4 | F2: 5 | G2: 5 | H2: 5 | I2: 4 | J2: 5 | K2: 4
A3: ARNITA NABABAN | B3: 5 | C3: 5 | D3: 4 | E3: 4 | F3: 4 | G3: 4 | H3: 5 | I3: 4 | J3: 5 | K3: 4
A4: MORES NABABAN | B4: 4 | C4: 5 | D4: 4 | E4: 5 | F4: 4 | G4: 4 | H4: 5 | I4: 3 | J4: 5 | K4: 4
A5: SARITUA MARPAUNG | B5: 5 | C5: 5 | D5: 5 | E5: 5 | F5: 5 | G5: 5 | H5: 5 | I5: 4 | J5: 5 | K5: 5
A6: ELSA NABABAN | B6: 4 | C6: 5 | D6: 4 | E6: 4 | F6: 4 | G6: 5 | H6: 5 | I6: 3 | J6: 5 | K6: 5
A7: HADI SAPUTRA | B7: 4 | C7: 4 | D7: 4 | E7: 5 | F7: 3 | G7: 4 | H7: 4 | I7: 2 | J7: 4 | K7: 5
A8: IRFAN AGUS | B8: 4 | C8: 4 | D8: 4 | E8: 5 | F8: 4 | G8: 4 | H8: 4 | I8: 3 | J8: 5 | K8: 5
A9: LESTARI SIBAGARIANG | B9: 4 | C9: 4 | D9: 4 | E9: 4 | F9: 3 | G9: 4 | H9: 4 | I9: 2 | J9: 4 | K9: 4
A10: JOSIA NABABAN | B10: 4 | C10: 4 | D10: 4 | E10: 4 | F10: 5 | G10: 5 | H10: 5 | I10: 4 | J10: 4 | K10: 5
A11: IRMA SIANIPAR | B11: 4 | C11: 5 | D11: 4 | E11: 4 | F11: 3 | G11: 4 | H11: 4 | I11: 3 | J11: 4 | K11: 5
A12: LAMTIUR NABABAN | B12: 4 | C12: 4 | D12: 3 | E12: 3 | F12: 4 | G12: 4 | H12: 4 | I12: 2 | J12: 4 | K12: 4
A13: RAHUL NABABAN | B13: 4 | C13: 3 | D13: 4 | E13: 4 | F13: 3 | G13: 4 | H13: 4 | I13: 2 | J13: 4 | K13: 4
... A21: JELMANRO SILITONGA | B21: 3 | C21: 3 | D21: 2 | E21: 3 | F21: 3 | G21: 3 | H21: 3 | I21: 2 | J21: 3 | K21: 3
A22: AI | B22: =MAX(B2:B21) -> 5 | C22: =MAX(C2:C21) -> 5 | D22: =MAX(D2:D21) -> 5 | E22: =MAX(E2:E21) -> 5 | F22: =MAX(F2:F21) -> 5 | G22: =MAX(G2:G21) -> 5 | H22: =MAX(H2:H21) -> 5 | I22: =MAX(I2:I21) -> 4 | ... K22: =MAX(K2:K21) -> 5
A23: AAI | B23: =min(B2:B21) -> 3 | C23: =min(C2:C21) -> 2 | D23: =min(D2:D21) -> 2 | E23: =min(E2:E21) -> 3 | F23: =min(F2:F21) -> 3 | G23: =min(G2:G21) -> 3 | H23: =min(H2:H21) -> 3 | I23: =min(I2:I21) -> 1 | ... K23: =min(K2:K21) -> 3
A26: NORMALISASI
A27: ALTERNATIF | B27: C1 | C27: C2 | D27: C3 | E27: C4 | F27: C5 | G27: C6 | H27: C7 | I27: C8 | J27: C9 | K27: C10
A28: AMANDA NABABAN | B28: =(B2-$B$23)/($B$22-$B$23) -> 1 | C28: =(C2-$C$23)/($C$22-$C$23) -> 1 | D28: =(D2-$D$23)/($D$22-$D$23) -> 1 | E28: =(E2-$E$23)/($E$22-$E$23) -> 0.5 | F28: =(F2-$F$23)/($F$22-$F$23) -> 1 | G28: =(G2-$G$23)/($G$22-$G$23) -> 1 | H28: =(H2-$H$23)/($H$22-$H$23) -> 1 | I28: =(I2-$I$23)/($I$22-$I$23) -> 1 | J28: =(J2-$J$23)/($J$22-$J$23) -> 1 | K28: =($K$22-K2)/($K$22-$K$23) -> 0.5
A29: ARNITA NABABAN | B29: =(B3-$B$23)/($B$22-$B$23) -> 1 | C29: =(C3-$C$23)/($C$22-$C$23) -> 1 | D29: =(D3-$D$23)/($D$22-$D$23) -> 0.66666667 | E29: =(E3-$E$23)/($E$22-$E$23) -> 0.5 | F29: =(F3-$F$23)/($F$22-$F$23) -> 0.5 | G29: =(G3-$G$23)/($G$22-$G$23) -> 0.5 | H29: =(H3-$H$23)/($H$22-$H$23) -> 1 | I29: =(I3-$I$23)/($I$22-$I$23) -> 1 | J29: =(J3-$J$23)/($J$22-$J$23) -> 1 | K29: =($K$22-K3)/($K$22-$K$23) -> 0.5
A30: MORES NABABAN | B30: =(B4-$B$23)/($B$22-$B$23) -> 0.5 | C30: =(C4-$C$23)/($C$22-$C$23) -> 1 | D30: =(D4-$D$23)/($D$22-$D$23) -> 0.66666667 | E30: =(E4-$E$23)/($E$22-$E$23) -> 1 | F30: =(F4-$F$23)/($F$22-$F$23) -> 0.5 | G30: =(G4-$G$23)/($G$22-$G$23) -> 0.5 | H30: =(H4-$H$23)/($H$22-$H$23) -> 1 | I30: =(I4-$I$23)/($I$22-$I$23) -> 0.66666667 | J30: =(J4-$J$23)/($J$22-$J$23) -> 1 | K30: =($K$22-K4)/($K$22-$K$23) -> 0.5
A31: SARITUA MARPAUNG | B31: =(B5-$B$23)/($B$22-$B$23) -> 1 | C31: =(C5-$C$23)/($C$22-$C$23) -> 1 | D31: =(D5-$D$23)/($D$22-$D$23) -> 1 | E31: =(E5-$E$23)/($E$22-$E$23) -> 1 | F31: =(F5-$F$23)/($F$22-$F$23) -> 1 | G31: =(G5-$G$23)/($G$22-$G$23) -> 1 | H31: =(H5-$H$23)/($H$22-$H$23) -> 1 | I31: =(I5-$I$23)/($I$22-$I$23) -> 1 | J31: =(J5-$J$23)/($J$22-$J$23) -> 1 | K31: =($K$22-K5)/($K$22-$K$23) -> 0
A32: ELSA NABABAN | B32: =(B6-$B$23)/($B$22-$B$23) -> 0.5 | C32: =(C6-$C$23)/($C$22-$C$23) -> 1 | D32: =(D6-$D$23)/($D$22-$D$23) -> 0.66666667 | E32: =(E6-$E$23)/($E$22-$E$23) -> 0.5 | F32: =(F6-$F$23)/($F$22-$F$23) -> 0.5 | G32: =(G6-$G$23)/($G$22-$G$23) -> 1 | H32: =(H6-$H$23)/($H$22-$H$23) -> 1 | I32: =(I6-$I$23)/($I$22-$I$23) -> 0.66666667 | J32: =(J6-$J$23)/($J$22-$J$23) -> 1 | K32: =($K$22-K6)/($K$22-$K$23) -> 0
A33: HADI SAPUTRA | B33: =(B7-$B$23)/($B$22-$B$23) -> 0.5 | C33: =(C7-$C$23)/($C$22-$C$23) -> 0.66666667 | D33: =(D7-$D$23)/($D$22-$D$23) -> 0.66666667 | E33: =(E7-$E$23)/($E$22-$E$23) -> 1 | F33: =(F7-$F$23)/($F$22-$F$23) -> 0 | G33: =(G7-$G$23)/($G$22-$G$23) -> 0.5 | H33: =(H7-$H$23)/($H$22-$H$23) -> 0.5 | I33: =(I7-$I$23)/($I$22-$I$23) -> 0.33333333 | J33: =(J7-$J$23)/($J$22-$J$23) -> 0.5 | K33: =($K$22-K7)/($K$22-$K$23) -> 0
A34: IRFAN AGUS | B34: =(B8-$B$23)/($B$22-$B$23) -> 0.5 | C34: =(C8-$C$23)/($C$22-$C$23) -> 0.66666667 | D34: =(D8-$D$23)/($D$22-$D$23) -> 0.66666667 | E34: =(E8-$E$23)/($E$22-$E$23) -> 1 | F34: =(F8-$F$23)/($F$22-$F$23) -> 0.5 | G34: =(G8-$G$23)/($G$22-$G$23) -> 0.5 | H34: =(H8-$H$23)/($H$22-$H$23) -> 0.5 | I34: =(I8-$I$23)/($I$22-$I$23) -> 0.66666667 | J34: =(J8-$J$23)/($J$22-$J$23) -> 1 | K34: =($K$22-K8)/($K$22-$K$23) -> 0
A35: LESTARI SIBAGARIANG | B35: =(B9-$B$23)/($B$22-$B$23) -> 0.5 | C35: =(C9-$C$23)/($C$22-$C$23) -> 0.66666667 | D35: =(D9-$D$23)/($D$22-$D$23) -> 0.66666667 | E35: =(E9-$E$23)/($E$22-$E$23) -> 0.5 | F35: =(F9-$F$23)/($F$22-$F$23) -> 0 | G35: =(G9-$G$23)/($G$22-$G$23) -> 0.5 | H35: =(H9-$H$23)/($H$22-$H$23) -> 0.5 | I35: =(I9-$I$23)/($I$22-$I$23) -> 0.33333333 | J35: =(J9-$J$23)/($J$22-$J$23) -> 0.5 | K35: =($K$22-K9)/($K$22-$K$23) -> 0.5
A36: JOSIA NABABAN | B36: =(B10-$B$23)/($B$22-$B$23) -> 0.5 | C36: =(C10-$C$23)/($C$22-$C$23) -> 0.66666667 | D36: =(D10-$D$23)/($D$22-$D$23) -> 0.66666667 | E36: =(E10-$E$23)/($E$22-$E$23) -> 0.5 | F36: =(F10-$F$23)/($F$22-$F$23) -> 1 | G36: =(G10-$G$23)/($G$22-$G$23) -> 1 | H36: =(H10-$H$23)/($H$22-$H$23) -> 1 | I36: =(I10-$I$23)/($I$22-$I$23) -> 1 | J36: =(J10-$J$23)/($J$22-$J$23) -> 0.5 | K36: =($K$22-K10)/($K$22-$K$23) -> 0
A37: IRMA SIANIPAR | B37: =(B11-$B$23)/($B$22-$B$23) -> 0.5 | C37: =(C11-$C$23)/($C$22-$C$23) -> 1 | D37: =(D11-$D$23)/($D$22-$D$23) -> 0.66666667 | E37: =(E11-$E$23)/($E$22-$E$23) -> 0.5 | F37: =(F11-$F$23)/($F$22-$F$23) -> 0 | G37: =(G11-$G$23)/($G$22-$G$23) -> 0.5 | H37: =(H11-$H$23)/($H$22-$H$23) -> 0.5 | I37: =(I11-$I$23)/($I$22-$I$23) -> 0.66666667 | J37: =(J11-$J$23)/($J$22-$J$23) -> 0.5 | K37: =($K$22-K11)/($K$22-$K$23) -> 0
A38: LAMTIUR NABABAN | B38: =(B12-$B$23)/($B$22-$B$23) -> 0.5 | C38: =(C12-$C$23)/($C$22-$C$23) -> 0.66666667 | D38: =(D12-$D$23)/($D$22-$D$23) -> 0.33333333 | E38: =(E12-$E$23)/($E$22-$E$23) -> 0 | F38: =(F12-$F$23)/($F$22-$F$23) -> 0.5 | G38: =(G12-$G$23)/($G$22-$G$23) -> 0.5 | H38: =(H12-$H$23)/($H$22-$H$23) -> 0.5 | I38: =(I12-$I$23)/($I$22-$I$23) -> 0.33333333 | J38: =(J12-$J$23)/($J$22-$J$23) -> 0.5 | K38: =($K$22-K12)/($K$22-$K$23) -> 0.5
A39: RAHUL NABABAN | B39: =(B13-$B$23)/($B$22-$B$23) -> 0.5 | C39: =(C13-$C$23)/($C$22-$C$23) -> 0.33333333 | D39: =(D13-$D$23)/($D$22-$D$23) -> 0.66666667 | E39: =(E13-$E$23)/($E$22-$E$23) -> 0.5 | F39: =(F13-$F$23)/($F$22-$F$23) -> 0 | G39: =(G13-$G$23)/($G$22-$G$23) -> 0.5 | H39: =(H13-$H$23)/($H$22-$H$23) -> 0.5 | I39: =(I13-$I$23)/($I$22-$I$23) -> 0.33333333 | J39: =(J13-$J$23)/($J$22-$J$23) -> 0.5 | K39: =($K$22-K13)/($K$22-$K$23) -> 0.5
... A47: JELMANRO SILITONGA | B47: =(B21-$B$23)/($B$22-$B$23) -> 0 | C47: =(C21-$C$23)/($C$22-$C$23) -> 0.33333333 | D47: =(D21-$D$23)/($D$22-$D$23) -> 0 | E47: =(E21-$E$23)/($E$22-$E$23) -> 0 | F47: =(F21-$F$23)/($F$22-$F$23) -> 0 | G47: =(G21-$G$23)/($G$22-$G$23) -> 0 | H47: =(H21-$H$23)/($H$22-$H$23) -> 0 | I47: =(I21-$I$23)/($I$22-$I$23) -> 0.33333333 | J47: =(J21-$J$23)/($J$22-$J$23) -> 0 | K47: =($K$22-K21)/($K$22-$K$23) -> 1
A48: NILAI AGREGAT | B48: =SUM(B28:B47) -> 8.5 | C48: =SUM(C28:C47) -> 12.666667 | D48: =SUM(D28:D47) -> 12.333333 | E48: =SUM(E28:E47) -> 8.5 | F48: =SUM(F28:F47) -> 6.5 | G48: =SUM(G28:G47) -> 9.5 | H48: =SUM(H28:H47) -> 12 | I48: =SUM(I28:I47) -> 10 | ... K48: =SUM(K28:K47) -> 8.5
A50: URUTAN PRIORITAS
A51: KRITERIA | B51: NILAI AGREGAT | C51: HASIL URUTAN DARI TERBESAR KE TERKECIL
A52: C1 | B52: =B48 -> 8.5 | C52: {=SORT(A52:A61,B52:B61,0)} -> C2 | D52: 1
A53: C2 | B53: =C48 -> 12.666667 | C53: C3 | D53: 2
A54: C3 | B54: =D48 -> 12.333333 | C54: C7 | D54: 3
A55: C4 | B55: =E48 -> 8.5 | C55: C9 | D55: 4
A56: C5 | B56: =F48 -> 6.5 | C56: C8 | D56: 5
A57: C6 | B57: =G48 -> 9.5 | C57: C6 | D57: 6
...

Sheet VIKOR
A1: ALTERNATIF | B1: C1 | C1: C2 | D1: C3 | E1: C4 | F1: C5 | G1: C6 | H1: C7 | I1: C8 | J1: C9 | K1: C10 | M1: Bobot FUCOM
A2: AMANDA NABABAN | B2: 5 | C2: 5 | D2: 5 | E2: 4 | F2: 5 | G2: 5 | H2: 5 | I2: 4 | J2: 5 | K2: 4 | M2: C1 | N2: =FUCOM!L89 -> 0.085
A3: ARNITA NABABAN | B3: 5 | C3: 5 | D3: 4 | E3: 4 | F3: 4 | G3: 4 | H3: 5 | I3: 4 | J3: 5 | K3: 4 | M3: C2 | N3: =FUCOM!L90 -> 0.12666667
A4: MORES NABABAN | B4: 4 | C4: 5 | D4: 4 | E4: 5 | F4: 4 | G4: 4 | H4: 5 | I4: 3 | J4: 5 | K4: 4 | M4: C3 | N4: =FUCOM!L91 -> 0.12333333
A5: SARITUA MARPAUNG | B5: 5 | C5: 5 | D5: 5 | E5: 5 | F5: 5 | G5: 5 | H5: 5 | I5: 4 | J5: 5 | K5: 5 | M5: C4 | N5: =FUCOM!L92 -> 0.085
A6: ELSA NABABAN | B6: 4 | C6: 5 | D6: 4 | E6: 4 | F6: 4 | G6: 5 | H6: 5 | I6: 3 | J6: 5 | K6: 5 | M6: C5 | N6: =FUCOM!L93 -> 0.065
A7: HADI SAPUTRA | B7: 4 | C7: 4 | D7: 4 | E7: 5 | F7: 3 | G7: 4 | H7: 4 | I7: 2 | J7: 4 | K7: 5 | M7: C6 | N7: =FUCOM!L94 -> 0.095
A8: IRFAN AGUS | B8: 4 | C8: 4 | D8: 4 | E8: 5 | F8: 4 | G8: 4 | H8: 4 | I8: 3 | J8: 5 | K8: 5 | M8: C7 | N8: =FUCOM!L95 -> 0.12
A9: LESTARI SIBAGARIANG | B9: 4 | C9: 4 | D9: 4 | E9: 4 | F9: 3 | G9: 4 | H9: 4 | I9: 2 | J9: 4 | K9: 4 | M9: C8 | N9: =FUCOM!L96 -> 0.1
A10: JOSIA NABABAN | B10: 4 | C10: 4 | D10: 4 | E10: 4 | F10: 5 | G10: 5 | H10: 5 | I10: 4 | J10: 4 | K10: 5 | M10: C9 | N10: =FUCOM!L97 -> 0.115
A11: IRMA SIANIPAR | B11: 4 | C11: 5 | D11: 4 | E11: 4 | F11: 3 | G11: 4 | H11: 4 | I11: 3 | J11: 4 | K11: 5 | M11: C10 | N11: =FUCOM!L98 -> 0.085
A12: LAMTIUR NABABAN | B12: 4 | C12: 4 | D12: 3 | E12: 3 | F12: 4 | G12: 4 | H12: 4 | I12: 2 | J12: 4 | K12: 4 | M12: Jumlah | N12: =SUM(N2:N11) -> 1
A13: RAHUL NABABAN | B13: 4 | C13: 3 | D13: 4 | E13: 4 | F13: 3 | G13: 4 | H13: 4 | I13: 2 | J13: 4 | K13: 4
A14: HOSIANA NABABAN | B14: 4 | C14: 4 | D14: 4 | E14: 3 | F14: 3 | G14: 3 | H14: 4 | I14: 2 | J14: 5 | K14: 4
A15: ESTER NABABAN | B15: 4 | C15: 3 | D15: 4 | E15: 4 | F15: 3 | G15: 4 | H15: 4 | I15: 2 | J15: 4 | K15: 3
A16: ANWAR NABABAN | B16: 3 | C16: 3 | D16: 3 | E16: 3 | F16: 4 | G16: 4 | H16: 4 | I16: 1 | J16: 3 | K16: 4
A17: MORISCA SIBAGARIANG | B17: 3 | C17: 3 | D17: 4 | E17: 3 | F17: 3 | G17: 3 | H17: 4 | I17: 1 | J17: 4 | K17: 4
A18: ELFRIDA SITINJAK | B18: 3 | C18: 4 | D18: 4 | E18: 4 | F18: 3 | G18: 3 | H18: 4 | I18: 3 | J18: 4 | K18: 5
A19: CREDO NABABAN | B19: 3 | C19: 3 | D19: 4 | E19: 3 | F19: 4 | G19: 3 | H19: 4 | I19: 2 | J19: 3 | K19: 3
A20: SERDI SILITONGA | B20: 3 | C20: 2 | D20: 3 | E20: 3 | F20: 3 | G20: 4 | H20: 3 | I20: 1 | J20: 3 | K20: 3
A21: JELMANRO SILITONGA | B21: 3 | C21: 3 | D21: 2 | E21: 3 | F21: 3 | G21: 3 | H21: 3 | I21: 2 | J21: 3 | K21: 3
A22: AI | B22: =MAX(B2:B21) -> 5 | C22: =MAX(C2:C21) -> 5 | D22: =MAX(D2:D21) -> 5 | E22: =MAX(E2:E21) -> 5 | F22: =MAX(F2:F21) -> 5 | G22: =MAX(G2:G21) -> 5 | H22: =MAX(H2:H21) -> 5 | I22: =MAX(I2:I21) -> 4 | ... K22: =MAX(K2:K21) -> 5
A23: AAI | B23: =min(B2:B21) -> 3 | C23: =min(C2:C21) -> 2 | D23: =min(D2:D21) -> 2 | E23: =min(E2:E21) -> 3 | F23: =min(F2:F21) -> 3 | G23: =min(G2:G21) -> 3 | H23: =min(H2:H21) -> 3 | I23: =min(I2:I21) -> 1 | ... K23: =min(K2:K21) -> 3
A25: NORMALISASI
A26: ALTERNATIF | B26: C1 | C26: C2 | D26: C3 | E26: C4 | F26: C5 | G26: C6 | H26: C7 | I26: C8 | J26: C9 | K26: C10
A27: AMANDA NABABAN | B27: =($B$22-B2)/($B$22-$B$23) -> 0 | C27: =($C$22-C2)/($C$22-$C$23) -> 0 | D27: =($D$22-D2)/($D$22-$D$23) -> 0 | E27: =($E$22-E2)/($E$22-$E$23) -> 0.5 | F27: =($F$22-F2)/($F$22-$F$23) -> 0 | G27: =($G$22-G2)/($G$22-$G$23) -> 0 | H27: =($H$22-H2)/($H$22-$H$23) -> 0 | I27: =($I$22-I2)/($I$22-$I$23) -> 0 | J27: =($J$22-J2)/($J$22-$J$23) -> 0 | K27: =($K$22-K2)/($K$22-$K$23) -> 0.5
A28: ARNITA NABABAN | B28: =($B$22-B3)/($B$22-$B$23) -> 0 | C28: =($C$22-C3)/($C$22-$C$23) -> 0 | D28: =($D$22-D3)/($D$22-$D$23) -> 0.33333333 | E28: =($E$22-E3)/($E$22-$E$23) -> 0.5 | F28: =($F$22-F3)/($F$22-$F$23) -> 0.5 | G28: =($G$22-G3)/($G$22-$G$23) -> 0.5 | H28: =($H$22-H3)/($H$22-$H$23) -> 0 | I28: =($I$22-I3)/($I$22-$I$23) -> 0 | J28: =($J$22-J3)/($J$22-$J$23) -> 0 | K28: =($K$22-K3)/($K$22-$K$23) -> 0.5
A29: MORES NABABAN | B29: =($B$22-B4)/($B$22-$B$23) -> 0.5 | C29: =($C$22-C4)/($C$22-$C$23) -> 0 | D29: =($D$22-D4)/($D$22-$D$23) -> 0.33333333 | E29: =($E$22-E4)/($E$22-$E$23) -> 0 | F29: =($F$22-F4)/($F$22-$F$23) -> 0.5 | G29: =($G$22-G4)/($G$22-$G$23) -> 0.5 | H29: =($H$22-H4)/($H$22-$H$23) -> 0 | I29: =($I$22-I4)/($I$22-$I$23) -> 0.33333333 | J29: =($J$22-J4)/($J$22-$J$23) -> 0 | K29: =($K$22-K4)/($K$22-$K$23) -> 0.5
A30: SARITUA MARPAUNG | B30: =($B$22-B5)/($B$22-$B$23) -> 0 | C30: =($C$22-C5)/($C$22-$C$23) -> 0 | D30: =($D$22-D5)/($D$22-$D$23) -> 0 | E30: =($E$22-E5)/($E$22-$E$23) -> 0 | F30: =($F$22-F5)/($F$22-$F$23) -> 0 | G30: =($G$22-G5)/($G$22-$G$23) -> 0 | H30: =($H$22-H5)/($H$22-$H$23) -> 0 | I30: =($I$22-I5)/($I$22-$I$23) -> 0 | J30: =($J$22-J5)/($J$22-$J$23) -> 0 | K30: =($K$22-K5)/($K$22-$K$23) -> 0
A31: ELSA NABABAN | B31: =($B$22-B6)/($B$22-$B$23) -> 0.5 | C31: =($C$22-C6)/($C$22-$C$23) -> 0 | D31: =($D$22-D6)/($D$22-$D$23) -> 0.33333333 | E31: =($E$22-E6)/($E$22-$E$23) -> 0.5 | F31: =($F$22-F6)/($F$22-$F$23) -> 0.5 | G31: =($G$22-G6)/($G$22-$G$23) -> 0 | H31: =($H$22-H6)/($H$22-$H$23) -> 0 | I31: =($I$22-I6)/($I$22-$I$23) -> 0.33333333 | J31: =($J$22-J6)/($J$22-$J$23) -> 0 | K31: =($K$22-K6)/($K$22-$K$23) -> 0
A32: HADI SAPUTRA | B32: =($B$22-B7)/($B$22-$B$23) -> 0.5 | C32: =($C$22-C7)/($C$22-$C$23) -> 0.33333333 | D32: =($D$22-D7)/($D$22-$D$23) -> 0.33333333 | E32: =($E$22-E7)/($E$22-$E$23) -> 0 | F32: =($F$22-F7)/($F$22-$F$23) -> 1 | G32: =($G$22-G7)/($G$22-$G$23) -> 0.5 | H32: =($H$22-H7)/($H$22-$H$23) -> 0.5 | I32: =($I$22-I7)/($I$22-$I$23) -> 0.66666667 | J32: =($J$22-J7)/($J$22-$J$23) -> 0.5 | K32: =($K$22-K7)/($K$22-$K$23) -> 0
A33: IRFAN AGUS | B33: =($B$22-B8)/($B$22-$B$23) -> 0.5 | C33: =($C$22-C8)/($C$22-$C$23) -> 0.33333333 | D33: =($D$22-D8)/($D$22-$D$23) -> 0.33333333 | E33: =($E$22-E8)/($E$22-$E$23) -> 0 | F33: =($F$22-F8)/($F$22-$F$23) -> 0.5 | G33: =($G$22-G8)/($G$22-$G$23) -> 0.5 | H33: =($H$22-H8)/($H$22-$H$23) -> 0.5 | I33: =($I$22-I8)/($I$22-$I$23) -> 0.33333333 | J33: =($J$22-J8)/($J$22-$J$23) -> 0 | K33: =($K$22-K8)/($K$22-$K$23) -> 0
A34: LESTARI SIBAGARIANG | B34: =($B$22-B9)/($B$22-$B$23) -> 0.5 | C34: =($C$22-C9)/($C$22-$C$23) -> 0.33333333 | D34: =($D$22-D9)/($D$22-$D$23) -> 0.33333333 | E34: =($E$22-E9)/($E$22-$E$23) -> 0.5 | F34: =($F$22-F9)/($F$22-$F$23) -> 1 | G34: =($G$22-G9)/($G$22-$G$23) -> 0.5 | H34: =($H$22-H9)/($H$22-$H$23) -> 0.5 | I34: =($I$22-I9)/($I$22-$I$23) -> 0.66666667 | J34: =($J$22-J9)/($J$22-$J$23) -> 0.5 | K34: =($K$22-K9)/($K$22-$K$23) -> 0.5
A35: JOSIA NABABAN | B35: =($B$22-B10)/($B$22-$B$23) -> 0.5 | C35: =($C$22-C10)/($C$22-$C$23) -> 0.33333333 | D35: =($D$22-D10)/($D$22-$D$23) -> 0.33333333 | E35: =($E$22-E10)/($E$22-$E$23) -> 0.5 | F35: =($F$22-F10)/($F$22-$F$23) -> 0 | G35: =($G$22-G10)/($G$22-$G$23) -> 0 | H35: =($H$22-H10)/($H$22-$H$23) -> 0 | I35: =($I$22-I10)/($I$22-$I$23) -> 0 | J35: =($J$22-J10)/($J$22-$J$23) -> 0.5 | K35: =($K$22-K10)/($K$22-$K$23) -> 0
A36: IRMA SIANIPAR | B36: =($B$22-B11)/($B$22-$B$23) -> 0.5 | C36: =($C$22-C11)/($C$22-$C$23) -> 0 | D36: =($D$22-D11)/($D$22-$D$23) -> 0.33333333 | E36: =($E$22-E11)/($E$22-$E$23) -> 0.5 | F36: =($F$22-F11)/($F$22-$F$23) -> 1 | G36: =($G$22-G11)/($G$22-$G$23) -> 0.5 | H36: =($H$22-H11)/($H$22-$H$23) -> 0.5 | I36: =($I$22-I11)/($I$22-$I$23) -> 0.33333333 | J36: =($J$22-J11)/($J$22-$J$23) -> 0.5 | K36: =($K$22-K11)/($K$22-$K$23) -> 0
A37: LAMTIUR NABABAN | B37: =($B$22-B12)/($B$22-$B$23) -> 0.5 | C37: =($C$22-C12)/($C$22-$C$23) -> 0.33333333 | D37: =($D$22-D12)/($D$22-$D$23) -> 0.66666667 | E37: =($E$22-E12)/($E$22-$E$23) -> 1 | F37: =($F$22-F12)/($F$22-$F$23) -> 0.5 | G37: =($G$22-G12)/($G$22-$G$23) -> 0.5 | H37: =($H$22-H12)/($H$22-$H$23) -> 0.5 | I37: =($I$22-I12)/($I$22-$I$23) -> 0.66666667 | J37: =($J$22-J12)/($J$22-$J$23) -> 0.5 | K37: =($K$22-K12)/($K$22-$K$23) -> 0.5
A38: RAHUL NABABAN | B38: =($B$22-B13)/($B$22-$B$23) -> 0.5 | C38: =($C$22-C13)/($C$22-$C$23) -> 0.66666667 | D38: =($D$22-D13)/($D$22-$D$23) -> 0.33333333 | E38: =($E$22-E13)/($E$22-$E$23) -> 0.5 | F38: =($F$22-F13)/($F$22-$F$23) -> 1 | G38: =($G$22-G13)/($G$22-$G$23) -> 0.5 | H38: =($H$22-H13)/($H$22-$H$23) -> 0.5 | I38: =($I$22-I13)/($I$22-$I$23) -> 0.66666667 | J38: =($J$22-J13)/($J$22-$J$23) -> 0.5 | K38: =($K$22-K13)/($K$22-$K$23) -> 0.5
... A46: JELMANRO SILITONGA | B46: =($B$22-B21)/($B$22-$B$23) -> 1 | C46: =($C$22-C21)/($C$22-$C$23) -> 0.66666667 | D46: =($D$22-D21)/($D$22-$D$23) -> 1 | E46: =($E$22-E21)/($E$22-$E$23) -> 1 | F46: =($F$22-F21)/($F$22-$F$23) -> 1 | G46: =($G$22-G21)/($G$22-$G$23) -> 1 | H46: =($H$22-H21)/($H$22-$H$23) -> 1 | I46: =($I$22-I21)/($I$22-$I$23) -> 0.66666667 | J46: =($J$22-J21)/($J$22-$J$23) -> 1 | K46: =($K$22-K21)/($K$22-$K$23) -> 1
A48: MENGHITUNG NILAI S & R & Q
A49: ALTERNATIF | B49: S | C49: R | D49: Q | E49: S (HASILNY SAMA KOK) | F49: S- | G49: S+ | H49: R- | I49: R+ | J49: V | K49: RANKING NAME
...

Sheet WPM
A1: ALTERNATIF | B1: C1 | C1: C2 | D1: C3 | E1: C4 | F1: C5 | G1: C6 | H1: C7 | I1: C8 | J1: C9 | K1: C10
A2: AMANDA NABABAN | B2: 5 | C2: 5 | D2: 5 | E2: 4 | F2: 5 | G2: 5 | H2: 5 | I2: 4 | J2: 5 | K2: 4
A3: ARNITA NABABAN | B3: 5 | C3: 5 | D3: 4 | E3: 4 | F3: 4 | G3: 4 | H3: 5 | I3: 4 | J3: 5 | K3: 4
A4: MORES NABABAN | B4: 4 | C4: 5 | D4: 4 | E4: 5 | F4: 4 | G4: 4 | H4: 5 | I4: 3 | J4: 5 | K4: 4
A5: SARITUA MARPAUNG | B5: 5 | C5: 5 | D5: 5 | E5: 5 | F5: 5 | G5: 5 | H5: 5 | I5: 4 | J5: 5 | K5: 5
A6: ELSA NABABAN | B6: 4 | C6: 5 | D6: 4 | E6: 4 | F6: 4 | G6: 5 | H6: 5 | I6: 3 | J6: 5 | K6: 5
A7: HADI SAPUTRA | B7: 4 | C7: 4 | D7: 4 | E7: 5 | F7: 3 | G7: 4 | H7: 4 | I7: 2 | J7: 4 | K7: 5
A8: IRFAN AGUS | B8: 4 | C8: 4 | D8: 4 | E8: 5 | F8: 4 | G8: 4 | H8: 4 | I8: 3 | J8: 5 | K8: 5
A9: LESTARI SIBAGARIANG | B9: 4 | C9: 4 | D9: 4 | E9: 4 | F9: 3 | G9: 4 | H9: 4 | I9: 2 | J9: 4 | K9: 4
A10: JOSIA NABABAN | B10: 4 | C10: 4 | D10: 4 | E10: 4 | F10: 5 | G10: 5 | H10: 5 | I10: 4 | J10: 4 | K10: 5
A11: IRMA SIANIPAR | B11: 4 | C11: 5 | D11: 4 | E11: 4 | F11: 3 | G11: 4 | H11: 4 | I11: 3 | J11: 4 | K11: 5
A12: LAMTIUR NABABAN | B12: 4 | C12: 4 | D12: 3 | E12: 3 | F12: 4 | G12: 4 | H12: 4 | I12: 2 | J12: 4 | K12: 4
A13: RAHUL NABABAN | B13: 4 | C13: 3 | D13: 4 | E13: 4 | F13: 3 | G13: 4 | H13: 4 | I13: 2 | J13: 4 | K13: 4
... A21: JELMANRO SILITONGA | B21: 3 | C21: 3 | D21: 2 | E21: 3 | F21: 3 | G21: 3 | H21: 3 | I21: 2 | J21: 3 | K21: 3
A22: AI | B22: =MAX(B2:B21) -> 5 | C22: =MAX(C2:C21) -> 5 | D22: =MAX(D2:D21) -> 5 | E22: =MAX(E2:E21) -> 5 | F22: =MAX(F2:F21) -> 5 | G22: =MAX(G2:G21) -> 5 | H22: =MAX(H2:H21) -> 5 | I22: =MAX(I2:I21) -> 4 | ... K22: =MAX(K2:K21) -> 5
A23: AAI | B23: =min(B2:B21) -> 3 | C23: =min(C2:C21) -> 2 | D23: =min(D2:D21) -> 2 | E23: =min(E2:E21) -> 3 | F23: =min(F2:F21) -> 3 | G23: =min(G2:G21) -> 3 | H23: =min(H2:H21) -> 3 | I23: =min(I2:I21) -> 1 | ... K23: =min(K2:K21) -> 3
A25: NORMALISASI
A26: ALTERNATIF | B26: C1 | C26: C2 | D26: C3 | E26: C4 | F26: C5 | G26: C6 | H26: C7 | I26: C8 | J26: C9 | K26: C10 | M26: BOBOT TIAP KRITERIA FUCOM
A27: AMANDA NABABAN | B27: =B2/$B$22 -> 1 | C27: =C2/$C$22 -> 1 | D27: =D2/$D$22 -> 1 | E27: =E2/$E$22 -> 0.8 | F27: =F2/$F$22 -> 1 | G27: =G2/$G$22 -> 1 | H27: =H2/$H$22 -> 1 | I27: =I2/$I$22 -> 1 | J27: =J2/$J$22 -> 1 | K27: =$K$23/K2 -> 0.75 | M27: C1 | N27: 0.085
A28: ARNITA NABABAN | B28: =B3/$B$22 -> 1 | C28: =C3/$C$22 -> 1 | D28: =D3/$D$22 -> 0.8 | E28: =E3/$E$22 -> 0.8 | F28: =F3/$F$22 -> 0.8 | G28: =G3/$G$22 -> 0.8 | H28: =H3/$H$22 -> 1 | I28: =I3/$I$22 -> 1 | J28: =J3/$J$22 -> 1 | K28: =$K$23/K3 -> 0.75 | M28: C2 | N28: 0.12666667
A29: MORES NABABAN | B29: =B4/$B$22 -> 0.8 | C29: =C4/$C$22 -> 1 | D29: =D4/$D$22 -> 0.8 | E29: =E4/$E$22 -> 1 | F29: =F4/$F$22 -> 0.8 | G29: =G4/$G$22 -> 0.8 | H29: =H4/$H$22 -> 1 | I29: =I4/$I$22 -> 0.75 | J29: =J4/$J$22 -> 1 | K29: =$K$23/K4 -> 0.75 | M29: C3 | N29: 0.12333333
A30: SARITUA MARPAUNG | B30: =B5/$B$22 -> 1 | C30: =C5/$C$22 -> 1 | D30: =D5/$D$22 -> 1 | E30: =E5/$E$22 -> 1 | F30: =F5/$F$22 -> 1 | G30: =G5/$G$22 -> 1 | H30: =H5/$H$22 -> 1 | I30: =I5/$I$22 -> 1 | J30: =J5/$J$22 -> 1 | K30: =$K$23/K5 -> 0.6 | M30: C4 | N30: 0.085
A31: ELSA NABABAN | B31: =B6/$B$22 -> 0.8 | C31: =C6/$C$22 -> 1 | D31: =D6/$D$22 -> 0.8 | E31: =E6/$E$22 -> 0.8 | F31: =F6/$F$22 -> 0.8 | G31: =G6/$G$22 -> 1 | H31: =H6/$H$22 -> 1 | I31: =I6/$I$22 -> 0.75 | J31: =J6/$J$22 -> 1 | K31: =$K$23/K6 -> 0.6 | M31: C5 | N31: 0.065
A32: HADI SAPUTRA | B32: =B7/$B$22 -> 0.8 | C32: =C7/$C$22 -> 0.8 | D32: =D7/$D$22 -> 0.8 | E32: =E7/$E$22 -> 1 | F32: =F7/$F$22 -> 0.6 | G32: =G7/$G$22 -> 0.8 | H32: =H7/$H$22 -> 0.8 | I32: =I7/$I$22 -> 0.5 | J32: =J7/$J$22 -> 0.8 | K32: =$K$23/K7 -> 0.6 | M32: C6 | N32: 0.095
A33: IRFAN AGUS | B33: =B8/$B$22 -> 0.8 | C33: =C8/$C$22 -> 0.8 | D33: =D8/$D$22 -> 0.8 | E33: =E8/$E$22 -> 1 | F33: =F8/$F$22 -> 0.8 | G33: =G8/$G$22 -> 0.8 | H33: =H8/$H$22 -> 0.8 | I33: =I8/$I$22 -> 0.75 | J33: =J8/$J$22 -> 1 | K33: =$K$23/K8 -> 0.6 | M33: C7 | N33: 0.12
